<mujoco model="ur5_workbench">
  <compiler angle="radian" meshdir="/home/lopatoj/ur5_workbench_ws/mjcf_data/assets/" texturedir="/home/lopatoj/ur5_workbench_ws/mjcf_data/assets/"/>
  <asset>
    <mesh name="robotiq_ft300" content_type="model/stl" file="full/robotiq_ft300.stl"/>
    <mesh name="robotiq_ft300-G-062-COUPLING_G-50-4M6-1D6_20181119" content_type="model/stl" file="full/robotiq_ft300-G-062-COUPLING_G-50-4M6-1D6_20181119.stl"/>
    <mesh file="full/base/base_0.obj" scale="1.0 1.0 1.0"/>
    <mesh file="full/base/base_1.obj" scale="1.0 1.0 1.0"/>
    <material name="material_base_0" specular="0.20000000000000004" shininess="1.0" rgba="0.52549020 0.52549020 0.52549020 1.0"/>
    <material name="material_base_1" specular="0.20000000000000004" shininess="1.0" rgba="0.06274510 0.06274510 0.06274510 1.0"/>
    <mesh file="full/shoulder/shoulder_0.obj" scale="1.0 1.0 1.0"/>
    <mesh file="full/shoulder/shoulder_1.obj" scale="1.0 1.0 1.0"/>
    <mesh file="full/shoulder/shoulder_2.obj" scale="1.0 1.0 1.0"/>
    <material name="material_shoulder_0" specular="0.20000000000000004" shininess="1.0" rgba="0.17647059 0.17647059 0.17647059 1.0"/>
    <material name="material_shoulder_1" specular="0.20000000000000004" shininess="1.0" rgba="0.06274510 0.06274510 0.06274510 1.0"/>
    <material name="material_shoulder_2" specular="0.20000000000000004" shininess="1.0" rgba="0.31372549 0.43529412 0.51372549 1.0"/>
    <mesh file="full/upperarm/upperarm_0.obj" scale="1.0 1.0 1.0"/>
    <mesh file="full/upperarm/upperarm_1.obj" scale="1.0 1.0 1.0"/>
    <mesh file="full/upperarm/upperarm_2.obj" scale="1.0 1.0 1.0"/>
    <mesh file="full/upperarm/upperarm_3.obj" scale="1.0 1.0 1.0"/>
    <material name="material_upperarm_0" specular="0.20000000000000004" shininess="1.0" rgba="0.14117647 0.14117647 0.14117647 1.0"/>
    <material name="material_upperarm_1" specular="0.20000000000000004" shininess="1.0" rgba="0.05098039 0.05098039 0.05098039 1.0"/>
    <material name="material_upperarm_2" specular="0.20000000000000004" shininess="1.0" rgba="0.25098039 0.34901961 0.40784314 1.0"/>
    <material name="material_upperarm_3" specular="0.20000000000000004" shininess="1.0" rgba="0.41960784 0.41960784 0.41960784 1.0"/>
    <mesh file="full/forearm/forearm_0.obj" scale="1.0 1.0 1.0"/>
    <mesh file="full/forearm/forearm_1.obj" scale="1.0 1.0 1.0"/>
    <mesh file="full/forearm/forearm_2.obj" scale="1.0 1.0 1.0"/>
    <material name="material_forearm_0" specular="0.20000000000000004" shininess="1.0" rgba="0.25098039 0.34901961 0.40784314 1.0"/>
    <material name="material_forearm_1" specular="0.20000000000000004" shininess="1.0" rgba="0.41960784 0.41960784 0.41960784 1.0"/>
    <material name="material_forearm_2" specular="0.20000000000000004" shininess="1.0" rgba="0.14117647 0.14117647 0.14117647 1.0"/>
    <mesh file="full/wrist1/wrist1_0.obj" scale="1.0 1.0 1.0"/>
    <mesh file="full/wrist1/wrist1_1.obj" scale="1.0 1.0 1.0"/>
    <mesh file="full/wrist1/wrist1_2.obj" scale="1.0 1.0 1.0"/>
    <material name="material_wrist1_0" specular="0.20000000000000004" shininess="1.0" rgba="0.05098039 0.05098039 0.05098039 1.0"/>
    <material name="material_wrist1_1" specular="0.20000000000000004" shininess="1.0" rgba="0.14117647 0.14117647 0.14117647 1.0"/>
    <material name="material_wrist1_2" specular="0.20000000000000004" shininess="1.0" rgba="0.25098039 0.34901961 0.40784314 1.0"/>
    <mesh file="full/wrist2/wrist2_0.obj" scale="1.0 1.0 1.0"/>
    <mesh file="full/wrist2/wrist2_1.obj" scale="1.0 1.0 1.0"/>
    <mesh file="full/wrist2/wrist2_2.obj" scale="1.0 1.0 1.0"/>
    <material name="material_wrist2_0" specular="0.20000000000000004" shininess="1.0" rgba="0.05098039 0.05098039 0.05098039 1.0"/>
    <material name="material_wrist2_1" specular="0.20000000000000004" shininess="1.0" rgba="0.14117647 0.14117647 0.14117647 1.0"/>
    <material name="material_wrist2_2" specular="0.20000000000000004" shininess="1.0" rgba="0.25098039 0.34901961 0.40784314 1.0"/>
    <mesh file="full/wrist3/wrist3_0.obj" scale="1.0 1.0 1.0"/>
    <mesh file="full/wrist3/wrist3_1.obj" scale="1.0 1.0 1.0"/>
    <material name="material_wrist3_0" specular="0.20000000000000004" shininess="1.0" rgba="0.21568627 0.21568627 0.21568627 1.0"/>
    <material name="material_wrist3_1" specular="0.20000000000000004" shininess="1.0" rgba="0.09803922 0.10196078 0.10980392 1.0"/>
    <mesh file="full/robotiq_base/robotiq_base_0.obj" scale="1.0 1.0 1.0"/>
    <mesh file="full/robotiq_base/robotiq_base_1.obj" scale="1.0 1.0 1.0"/>
    <material name="material_robotiq_base_0" specular="0.20000000000000004" shininess="1.0" rgba="0.03137255 0.03137255 0.03137255 1.0"/>
    <material name="material_robotiq_base_1" specular="0.20000000000000004" shininess="1.0" rgba="0.80000000 0.80000000 0.80000000 1.0"/>
    <mesh file="full/left_knuckle/left_knuckle.obj" scale="1.0 1.0 1.0"/>
    <material name="material_left_knuckle_0" specular="0.20000000000000004" shininess="1.0" rgba="0.80000000 0.80000000 0.80000000 1.0"/>
    <mesh file="full/right_knuckle/right_knuckle.obj" scale="1.0 1.0 1.0"/>
    <material name="material_right_knuckle_0" specular="0.20000000000000004" shininess="1.0" rgba="0.80000000 0.80000000 0.80000000 1.0"/>
    <mesh file="full/left_finger/left_finger_0.obj" scale="1.0 1.0 1.0"/>
    <mesh file="full/left_finger/left_finger_1.obj" scale="1.0 1.0 1.0"/>
    <material name="material_left_finger_0" specular="0.20000000000000004" shininess="1.0" rgba="0.80000000 0.80000000 0.80000000 1.0"/>
    <material name="material_left_finger_1" specular="0.20000000000000004" shininess="1.0" rgba="0.03137255 0.03137255 0.03137255 1.0"/>
    <mesh file="full/right_finger/right_finger_0.obj" scale="1.0 1.0 1.0"/>
    <mesh file="full/right_finger/right_finger_1.obj" scale="1.0 1.0 1.0"/>
    <material name="material_right_finger_0" specular="0.20000000000000004" shininess="1.0" rgba="0.80000000 0.80000000 0.80000000 1.0"/>
    <material name="material_right_finger_1" specular="0.20000000000000004" shininess="1.0" rgba="0.03137255 0.03137255 0.03137255 1.0"/>
    <mesh file="full/left_inner_knuckle/left_inner_knuckle_0.obj" scale="1.0 1.0 1.0"/>
    <mesh file="full/left_inner_knuckle/left_inner_knuckle_1.obj" scale="1.0 1.0 1.0"/>
    <material name="material_left_inner_knuckle_0" specular="0.20000000000000004" shininess="1.0" rgba="0.03137255 0.03137255 0.03137255 1.0"/>
    <material name="material_left_inner_knuckle_1" specular="0.20000000000000004" shininess="1.0" rgba="0.80000000 0.80000000 0.80000000 1.0"/>
    <mesh file="full/right_inner_knuckle/right_inner_knuckle_0.obj" scale="1.0 1.0 1.0"/>
    <mesh file="full/right_inner_knuckle/right_inner_knuckle_1.obj" scale="1.0 1.0 1.0"/>
    <material name="material_right_inner_knuckle_0" specular="0.20000000000000004" shininess="1.0" rgba="0.03137255 0.03137255 0.03137255 1.0"/>
    <material name="material_right_inner_knuckle_1" specular="0.20000000000000004" shininess="1.0" rgba="0.80000000 0.80000000 0.80000000 1.0"/>
    <mesh file="full/left_finger_tip/left_finger_tip_0.obj" scale="1.0 1.0 1.0"/>
    <mesh file="full/left_finger_tip/left_finger_tip_1.obj" scale="1.0 1.0 1.0"/>
    <material name="material_left_finger_tip_0" specular="0.20000000000000004" shininess="1.0" rgba="0.03137255 0.03137255 0.03137255 1.0"/>
    <material name="material_left_finger_tip_1" specular="0.20000000000000004" shininess="1.0" rgba="0.80000000 0.80000000 0.80000000 1.0"/>
    <mesh file="full/right_finger_tip/right_finger_tip_0.obj" scale="1.0 1.0 1.0"/>
    <mesh file="full/right_finger_tip/right_finger_tip_1.obj" scale="1.0 1.0 1.0"/>
    <material name="material_right_finger_tip_0" specular="0.20000000000000004" shininess="1.0" rgba="0.03137255 0.03137255 0.03137255 1.0"/>
    <material name="material_right_finger_tip_1" specular="0.20000000000000004" shininess="1.0" rgba="0.80000000 0.80000000 0.80000000 1.0"/>
  </asset>
  <worldbody>
    <body name="thing1_shoulder_link" pos="1.905 0.381 0.089159" quat="-0.707107 0 0 0.707107">
      <inertial pos="0 -0.00193 -0.02561" mass="3.7" diaginertia="0.0149724 0.0149724 0.0104063"/>
      <joint name="thing1_shoulder_pan_joint" pos="0 0 0" axis="0 0 1" range="-6.28319 6.28319" actuatorfrcrange="-150 150"/>
      <body name="thing1_upper_arm_link" quat="0.707107 0.707107 0 0">
        <inertial pos="-0.2125 0 0.11336" mass="8.393" diaginertia="0.133886 0.133886 0.0151074"/>
        <joint name="thing1_shoulder_lift_joint" pos="0 0 0" axis="0 0 1" range="-6.28319 6.28319" actuatorfrcrange="-150 150"/>
        <body name="thing1_forearm_link" pos="-0.425 0 0">
          <inertial pos="-0.24225 0 0.0265" mass="2.33" diaginertia="0.0312168 0.0312168 0.004095"/>
          <joint name="thing1_elbow_joint" pos="0 0 0" axis="0 0 1" range="-3.14159 3.14159" actuatorfrcrange="-150 150"/>
          <body name="thing1_wrist_1_link" pos="-0.39225 0 0.10915">
            <inertial pos="0 -0.01634 -0.0018" quat="0.5 0.5 -0.5 0.5" mass="1.219" diaginertia="0.0021942 0.00201389 0.00201389"/>
            <joint name="thing1_wrist_1_joint" pos="0 0 0" axis="0 0 1" range="-6.28319 6.28319" actuatorfrcrange="-28 28"/>
            <body name="thing1_wrist_2_link" pos="0 -0.09465 -1.9413e-11" quat="0.707107 0.707107 0 0">
              <inertial pos="0 0.01634 -0.0018" quat="0.5 0.5 -0.5 0.5" mass="1.219" diaginertia="0.0021942 0.00183104 0.00183104"/>
              <joint name="thing1_wrist_2_joint" pos="0 0 0" axis="0 0 1" range="-6.28319 6.28319" actuatorfrcrange="-28 28"/>
              <body name="thing1_wrist_3_link" pos="0 0.0823 -1.688e-11" quat="0.707107 -0.707107 0 0">
                <inertial pos="-0.000226932 -0.000162966 0.0453767" quat="0.706316 -0.000320542 0.00380304 0.707886" mass="1.1511" diaginertia="0.00192005 0.00185119 0.00074602"/>
                <joint name="thing1_wrist_3_joint" pos="0 0 0" axis="0 0 1" range="-6.28319 6.28319" actuatorfrcrange="-28 28"/>
                <body name="thing1_robotiq_85_left_knuckle_link" pos="0.0306011 0 0.0924045" quat="-1 0 0 0">
                  <inertial pos="0.0280921 -0.000550523 0.00570126" quat="0.699112 0.212074 0.213677 0.648544" mass="0.0564515" diaginertia="1.95637e-05 1.76663e-05 9.3792e-06"/>
                  <joint name="thing1_robotiq_85_left_knuckle_joint" pos="0 0 0" axis="0 -1 0" range="0 0.8" actuatorfrcrange="-50 50" armature="0.5" frictionloss="5.0"/>
                  <body name="thing1_robotiq_85_left_finger_tip_link" pos="0.0371575 0 0.0434217">
                    <inertial pos="-0.0145671 -0.0008 0.016497" quat="0.977773 0 -0.209665 0" mass="0.0426859" diaginertia="1.20653e-05 1.19789e-05 2.64405e-06"/>
                    <joint name="thing1_robotiq_85_left_finger_tip_joint" pos="0 0 0" axis="0 -1 0"/>
                    <geom mesh="left_finger_tip_0" material="material_left_finger_tip_1" class="visual" pos="" quat=""/>
                    <geom mesh="left_finger_tip_1" material="material_left_finger_tip_0" class="visual" pos="" quat=""/>
                    <geom mesh="left_finger_tip_0" class="collision" pos="" quat=""/>
                    <geom mesh="left_finger_tip_1" class="collision" pos="" quat=""/>
                    <site name="thing1_robotiq_85_left_finger_tip_link" pos="0 0 0" quat="1.0 0 0 0"/>
                  </body>
                  <geom material="material_left_knuckle_0" mesh="left_knuckle" class="visual" pos="" quat=""/>
                  <geom mesh="left_knuckle" class="collision" pos="" quat=""/>
                  <geom mesh="left_finger_0" material="material_left_finger_1" class="visual" pos="0.0315262 0 -0.00376347" quat=""/>
                  <geom mesh="left_finger_1" material="material_left_finger_0" class="visual" pos="0.0315262 0 -0.00376347" quat=""/>
                  <geom mesh="left_finger_0" class="collision" pos="0.0315262 0 -0.00376347" quat=""/>
                  <geom mesh="left_finger_1" class="collision" pos="0.0315262 0 -0.00376347" quat=""/>
                  <site name="thing1_robotiq_85_left_knuckle_link" pos="0 0 0" quat="1.0 0 0 0"/>
                  <site name="thing1_robotiq_85_left_finger_link" pos="0.03152616 0 -0.00376347" quat="1.0 0 0 0"/>
                </body>
                <body name="thing1_robotiq_85_right_knuckle_link" pos="-0.0306011 0 0.0924045" quat="-1 0 0 0">
                  <inertial pos="-0.0280921 4.48872e-05 0.00570126" quat="0.669099 -0.212862 -0.212522 0.679581" mass="0.0564515" diaginertia="1.95514e-05 1.7665e-05 9.37296e-06"/>
                  <joint name="thing1_robotiq_85_right_knuckle_joint" pos="0 0 0" axis="0 -1 0" range="-0.8 0" actuatorfrcrange="-50 50" armature="0.5" frictionloss="5.0"/>
                  <body name="thing1_robotiq_85_right_finger_tip_link" pos="-0.0371575 0 0.0434217">
                    <inertial pos="0.0145671 5e-05 0.016497" quat="0.977773 0 0.209665 0" mass="0.0426859" diaginertia="1.20653e-05 1.19789e-05 2.64405e-06"/>
                    <joint name="thing1_robotiq_85_right_finger_tip_joint" pos="0 0 0" axis="0 -1 0"/>
                    <geom mesh="right_finger_tip_0" material="material_right_finger_tip_1" class="visual" pos="" quat=""/>
                    <geom mesh="right_finger_tip_1" material="material_right_finger_tip_0" class="visual" pos="" quat=""/>
                    <geom mesh="right_finger_tip_0" class="collision" pos="" quat=""/>
                    <geom mesh="right_finger_tip_1" class="collision" pos="" quat=""/>
                    <site name="thing1_robotiq_85_right_finger_tip_link" pos="0 0 0" quat="1.0 0 0 0"/>
                  </body>
                  <geom material="material_right_knuckle_0" mesh="right_knuckle" class="visual" pos="" quat=""/>
                  <geom mesh="right_knuckle" class="collision" pos="" quat=""/>
                  <geom mesh="right_finger_0" material="material_right_finger_1" class="visual" pos="-0.0315262 0 -0.00376347" quat=""/>
                  <geom mesh="right_finger_1" material="material_right_finger_0" class="visual" pos="-0.0315262 0 -0.00376347" quat=""/>
                  <geom mesh="right_finger_0" class="collision" pos="-0.0315262 0 -0.00376347" quat=""/>
                  <geom mesh="right_finger_1" class="collision" pos="-0.0315262 0 -0.00376347" quat=""/>
                  <site name="thing1_robotiq_85_right_knuckle_link" pos="0 0 0" quat="1.0 0 0 0"/>
                  <site name="thing1_robotiq_85_right_finger_link" pos="-0.03152616 0 -0.00376347" quat="1.0 0 0 0"/>
                </body>
                <body name="thing1_robotiq_85_left_inner_knuckle_link" pos="0.0127 0 0.09892" quat="-1 0 0 0">
                  <inertial pos="0.018977 0.00015001 0.022471" quat="0.939613 0 0.342237 0" mass="0.0296938" diaginertia="1.28757e-05 8.69056e-06 4.88712e-06"/>
                  <joint name="thing1_robotiq_85_left_inner_knuckle_joint" pos="0 0 0" axis="0 -1 0"/>
                  <geom mesh="left_inner_knuckle_0" material="material_left_inner_knuckle_1" class="visual" pos="" quat=""/>
                  <geom mesh="left_inner_knuckle_1" material="material_left_inner_knuckle_0" class="visual" pos="" quat=""/>
                  <geom mesh="left_inner_knuckle_0" class="collision" pos="" quat=""/>
                  <geom mesh="left_inner_knuckle_1" class="collision" pos="" quat=""/>
                  <site name="thing1_robotiq_85_left_inner_knuckle_link" pos="0 0 0" quat="1.0 0 0 0"/>
                </body>
                <body name="thing1_robotiq_85_right_inner_knuckle_link" pos="-0.0127 0 0.09892" quat="-1 0 0 0">
                  <inertial pos="-0.0192682 5.001e-05 0.0222218" quat="0.936371 0 -0.351012 0" mass="0.0296938" diaginertia="1.2882e-05 8.69056e-06 4.88076e-06"/>
                  <joint name="thing1_robotiq_85_right_inner_knuckle_joint" pos="0 0 0" axis="0 -1 0"/>
                  <geom mesh="right_inner_knuckle_0" material="material_right_inner_knuckle_1" class="visual" pos="" quat=""/>
                  <geom mesh="right_inner_knuckle_1" material="material_right_inner_knuckle_0" class="visual" pos="" quat=""/>
                  <geom mesh="right_inner_knuckle_0" class="collision" pos="" quat=""/>
                  <geom mesh="right_inner_knuckle_1" class="collision" pos="" quat=""/>
                  <site name="thing1_robotiq_85_right_inner_knuckle_link" pos="0 0 0" quat="1.0 0 0 0"/>
                </body>
                <geom mesh="wrist3_0" material="material_wrist3_1" class="visual" pos="0 0 -0.0818" quat="0.707107 0.707107 0 0"/>
                <geom mesh="wrist3_1" material="material_wrist3_0" class="visual" pos="0 0 -0.0818" quat="0.707107 0.707107 0 0"/>
                <geom mesh="wrist3_0" class="collision" pos="0 0 -0.0818" quat="0.707107 0.707107 0 0"/>
                <geom mesh="wrist3_1" class="collision" pos="0 0 -0.0818" quat="0.707107 0.707107 0 0"/>
                <geom mesh="robotiq_base_0" material="material_robotiq_base_1" class="visual" pos="0 0 0.0375" quat="-1 0 0 0"/>
                <geom mesh="robotiq_base_1" material="material_robotiq_base_0" class="visual" pos="0 0 0.0375" quat="-1 0 0 0"/>
                <geom mesh="robotiq_base_0" class="collision" pos="0 0 0.0375" quat="-1 0 0 0"/>
                <geom mesh="robotiq_base_1" class="collision" pos="0 0 0.0375" quat="-1 0 0 0"/>
                <geom pos="0 0 -0.004" quat="0.707107 0 0 -0.707107" type="mesh" mesh="robotiq_ft300-G-062-COUPLING_G-50-4M6-1D6_20181119" class="collision"/>
                <geom pos="0 0 -0.004" quat="0.707107 0 0 -0.707107" type="mesh" rgba="0.4 0.4 0.4 1" mesh="robotiq_ft300-G-062-COUPLING_G-50-4M6-1D6_20181119" class="visual"/>
                <geom pos="0 0 0.0375" quat="0 0.707107 0.707107 0" type="mesh" mesh="robotiq_ft300" class="collision"/>
                <geom pos="0 0 0.0375" quat="0 0.707107 0.707107 0" type="mesh" rgba="0.2 0.2 0.2 1" mesh="robotiq_ft300" class="visual"/>
                <site name="thing1_wrist_3_link" pos="0 0 0" quat="1.0 0 0 0"/>
                <site name="thing1_ft_frame" pos="0 0 0" quat="0 1.0 0 0"/>
                <site name="thing1_flange" pos="0 0 0" quat="-0.5000000000000001 0.5 0.5000000000000001 0.49999999999999994"/>
                <site name="thing1_tool0" pos="0 0 0" quat="1.0 0 0 0"/>
                <site name="thing1_ft300_sensor" pos="0 0 0.037500000000000006" quat="0 0.7071067811865475 0.7071067811865476 0"/>
                <site name="thing1_ft300_mounting_plate" pos="0 0 -0.004" quat="0.7071067811865476 0 0 -0.7071067811865475"/>
                <site name="thing1_robotiq_ft_frame_id" pos="0 0 0.037500000000000006" quat="1.0 0 0 0"/>
                <site name="thing1_robotiq_85_base_link" pos="0 0 0.037500000000000006" quat="1.0 0 0 0"/>
                <site name="thing1_tcp_frame" pos="0 0 0.17250000000000001" quat="1.0 0 0 0"/>
              </body>
              <geom mesh="wrist2_0" material="material_wrist2_2" class="visual" pos="0 0 -0.095" quat="1 0 0 0"/>
              <geom mesh="wrist2_1" material="material_wrist2_1" class="visual" pos="0 0 -0.095" quat="1 0 0 0"/>
              <geom mesh="wrist2_2" material="material_wrist2_0" class="visual" pos="0 0 -0.095" quat="1 0 0 0"/>
              <geom mesh="wrist2_0" class="collision" pos="0 0 -0.095" quat="1 0 0 0"/>
              <geom mesh="wrist2_1" class="collision" pos="0 0 -0.095" quat="1 0 0 0"/>
              <geom mesh="wrist2_2" class="collision" pos="0 0 -0.095" quat="1 0 0 0"/>
              <site name="thing1_wrist_2_link" pos="0 0 0" quat="1.0 0 0 0"/>
            </body>
            <geom mesh="wrist1_0" material="material_wrist1_2" class="visual" pos="0 0 -0.093" quat="0.707107 0.707107 0 0"/>
            <geom mesh="wrist1_1" material="material_wrist1_1" class="visual" pos="0 0 -0.093" quat="0.707107 0.707107 0 0"/>
            <geom mesh="wrist1_2" material="material_wrist1_0" class="visual" pos="0 0 -0.093" quat="0.707107 0.707107 0 0"/>
            <geom mesh="wrist1_0" class="collision" pos="0 0 -0.093" quat="0.707107 0.707107 0 0"/>
            <geom mesh="wrist1_1" class="collision" pos="0 0 -0.093" quat="0.707107 0.707107 0 0"/>
            <geom mesh="wrist1_2" class="collision" pos="0 0 -0.093" quat="0.707107 0.707107 0 0"/>
            <site name="thing1_wrist_1_link" pos="0 0 0" quat="1.0 0 0 0"/>
          </body>
          <geom mesh="forearm_0" material="material_forearm_2" class="visual" pos="0 0 0.0165" quat="0.5 0.5 -0.5 -0.5"/>
          <geom mesh="forearm_1" material="material_forearm_1" class="visual" pos="0 0 0.0165" quat="0.5 0.5 -0.5 -0.5"/>
          <geom mesh="forearm_2" material="material_forearm_0" class="visual" pos="0 0 0.0165" quat="0.5 0.5 -0.5 -0.5"/>
          <geom mesh="forearm_0" class="collision" pos="0 0 0.0165" quat="0.5 0.5 -0.5 -0.5"/>
          <geom mesh="forearm_1" class="collision" pos="0 0 0.0165" quat="0.5 0.5 -0.5 -0.5"/>
          <geom mesh="forearm_2" class="collision" pos="0 0 0.0165" quat="0.5 0.5 -0.5 -0.5"/>
          <site name="thing1_forearm_link" pos="0 0 0" quat="1.0 0 0 0"/>
        </body>
        <geom mesh="upperarm_0" material="material_upperarm_3" class="visual" pos="0 0 0.13585" quat="0.5 0.5 -0.5 -0.5"/>
        <geom mesh="upperarm_1" material="material_upperarm_2" class="visual" pos="0 0 0.13585" quat="0.5 0.5 -0.5 -0.5"/>
        <geom mesh="upperarm_2" material="material_upperarm_1" class="visual" pos="0 0 0.13585" quat="0.5 0.5 -0.5 -0.5"/>
        <geom mesh="upperarm_3" material="material_upperarm_0" class="visual" pos="0 0 0.13585" quat="0.5 0.5 -0.5 -0.5"/>
        <geom mesh="upperarm_0" class="collision" pos="0 0 0.13585" quat="0.5 0.5 -0.5 -0.5"/>
        <geom mesh="upperarm_1" class="collision" pos="0 0 0.13585" quat="0.5 0.5 -0.5 -0.5"/>
        <geom mesh="upperarm_2" class="collision" pos="0 0 0.13585" quat="0.5 0.5 -0.5 -0.5"/>
        <geom mesh="upperarm_3" class="collision" pos="0 0 0.13585" quat="0.5 0.5 -0.5 -0.5"/>
        <site name="thing1_upper_arm_link" pos="0 0 0" quat="1.0 0 0 0"/>
      </body>
      <geom mesh="shoulder_0" material="material_shoulder_2" class="visual" pos="" quat="0 0 0 1"/>
      <geom mesh="shoulder_1" material="material_shoulder_1" class="visual" pos="" quat="0 0 0 1"/>
      <geom mesh="shoulder_2" material="material_shoulder_0" class="visual" pos="" quat="0 0 0 1"/>
      <geom mesh="shoulder_0" class="collision" pos="" quat="0 0 0 1"/>
      <geom mesh="shoulder_1" class="collision" pos="" quat="0 0 0 1"/>
      <geom mesh="shoulder_2" class="collision" pos="" quat="0 0 0 1"/>
      <site name="thing1_shoulder_link" pos="0 0 0" quat="1.0 0 0 0"/>
    </body>
    <body name="thing2_shoulder_link" pos="0.381 0.381 0.089159" quat="-0.707107 0 0 0.707107">
      <inertial pos="0 -0.00193 -0.02561" mass="3.7" diaginertia="0.0149724 0.0149724 0.0104063"/>
      <joint name="thing2_shoulder_pan_joint" pos="0 0 0" axis="0 0 1" range="-6.28319 6.28319" actuatorfrcrange="-150 150"/>
      <body name="thing2_upper_arm_link" quat="0.707107 0.707107 0 0">
        <inertial pos="-0.2125 0 0.11336" mass="8.393" diaginertia="0.133886 0.133886 0.0151074"/>
        <joint name="thing2_shoulder_lift_joint" pos="0 0 0" axis="0 0 1" range="-6.28319 6.28319" actuatorfrcrange="-150 150"/>
        <body name="thing2_forearm_link" pos="-0.425 0 0">
          <inertial pos="-0.24225 0 0.0265" mass="2.33" diaginertia="0.0312168 0.0312168 0.004095"/>
          <joint name="thing2_elbow_joint" pos="0 0 0" axis="0 0 1" range="-3.14159 3.14159" actuatorfrcrange="-150 150"/>
          <body name="thing2_wrist_1_link" pos="-0.39225 0 0.10915">
            <inertial pos="0 -0.01634 -0.0018" quat="0.5 0.5 -0.5 0.5" mass="1.219" diaginertia="0.0021942 0.00201389 0.00201389"/>
            <joint name="thing2_wrist_1_joint" pos="0 0 0" axis="0 0 1" range="-6.28319 6.28319" actuatorfrcrange="-28 28"/>
            <body name="thing2_wrist_2_link" pos="0 -0.09465 -1.9413e-11" quat="0.707107 0.707107 0 0">
              <inertial pos="0 0.01634 -0.0018" quat="0.5 0.5 -0.5 0.5" mass="1.219" diaginertia="0.0021942 0.00183104 0.00183104"/>
              <joint name="thing2_wrist_2_joint" pos="0 0 0" axis="0 0 1" range="-6.28319 6.28319" actuatorfrcrange="-28 28"/>
              <body name="thing2_wrist_3_link" pos="0 0.0823 -1.688e-11" quat="0.707107 -0.707107 0 0">
                <inertial pos="-0.000226932 -0.000162966 0.0453767" quat="0.706316 -0.000320542 0.00380304 0.707886" mass="1.1511" diaginertia="0.00192005 0.00185119 0.00074602"/>
                <joint name="thing2_wrist_3_joint" pos="0 0 0" axis="0 0 1" range="-6.28319 6.28319" actuatorfrcrange="-28 28"/>
                <body name="thing2_robotiq_85_left_knuckle_link" pos="0.0306011 0 0.0924045" quat="-1 0 0 0">
                  <inertial pos="0.0280921 -0.000550523 0.00570126" quat="0.699112 0.212074 0.213677 0.648544" mass="0.0564515" diaginertia="1.95637e-05 1.76663e-05 9.3792e-06"/>
                  <joint name="thing2_robotiq_85_left_knuckle_joint" pos="0 0 0" axis="0 -1 0" range="0 0.8" actuatorfrcrange="-50 50" armature="0.5" frictionloss="5.0"/>
                  <body name="thing2_robotiq_85_left_finger_tip_link" pos="0.0371575 0 0.0434217">
                    <inertial pos="-0.0145671 -0.0008 0.016497" quat="0.977773 0 -0.209665 0" mass="0.0426859" diaginertia="1.20653e-05 1.19789e-05 2.64405e-06"/>
                    <joint name="thing2_robotiq_85_left_finger_tip_joint" pos="0 0 0" axis="0 -1 0"/>
                    <geom mesh="left_finger_tip_0" material="material_left_finger_tip_1" class="visual" pos="" quat=""/>
                    <geom mesh="left_finger_tip_1" material="material_left_finger_tip_0" class="visual" pos="" quat=""/>
                    <geom mesh="left_finger_tip_0" class="collision" pos="" quat=""/>
                    <geom mesh="left_finger_tip_1" class="collision" pos="" quat=""/>
                    <site name="thing2_robotiq_85_left_finger_tip_link" pos="0 0 0" quat="1.0 0 0 0"/>
                  </body>
                  <geom material="material_left_knuckle_0" mesh="left_knuckle" class="visual" pos="" quat=""/>
                  <geom mesh="left_knuckle" class="collision" pos="" quat=""/>
                  <geom mesh="left_finger_0" material="material_left_finger_1" class="visual" pos="0.0315262 0 -0.00376347" quat=""/>
                  <geom mesh="left_finger_1" material="material_left_finger_0" class="visual" pos="0.0315262 0 -0.00376347" quat=""/>
                  <geom mesh="left_finger_0" class="collision" pos="0.0315262 0 -0.00376347" quat=""/>
                  <geom mesh="left_finger_1" class="collision" pos="0.0315262 0 -0.00376347" quat=""/>
                  <site name="thing2_robotiq_85_left_knuckle_link" pos="0 0 0" quat="1.0 0 0 0"/>
                  <site name="thing2_robotiq_85_left_finger_link" pos="0.03152616 0 -0.00376347" quat="1.0 0 0 0"/>
                </body>
                <body name="thing2_robotiq_85_right_knuckle_link" pos="-0.0306011 0 0.0924045" quat="-1 0 0 0">
                  <inertial pos="-0.0280921 4.48872e-05 0.00570126" quat="0.669099 -0.212862 -0.212522 0.679581" mass="0.0564515" diaginertia="1.95514e-05 1.7665e-05 9.37296e-06"/>
                  <joint name="thing2_robotiq_85_right_knuckle_joint" pos="0 0 0" axis="0 -1 0" range="-0.8 0" actuatorfrcrange="-50 50" armature="0.5" frictionloss="5.0"/>
                  <body name="thing2_robotiq_85_right_finger_tip_link" pos="-0.0371575 0 0.0434217">
                    <inertial pos="0.0145671 5e-05 0.016497" quat="0.977773 0 0.209665 0" mass="0.0426859" diaginertia="1.20653e-05 1.19789e-05 2.64405e-06"/>
                    <joint name="thing2_robotiq_85_right_finger_tip_joint" pos="0 0 0" axis="0 -1 0"/>
                    <geom mesh="right_finger_tip_0" material="material_right_finger_tip_1" class="visual" pos="" quat=""/>
                    <geom mesh="right_finger_tip_1" material="material_right_finger_tip_0" class="visual" pos="" quat=""/>
                    <geom mesh="right_finger_tip_0" class="collision" pos="" quat=""/>
                    <geom mesh="right_finger_tip_1" class="collision" pos="" quat=""/>
                    <site name="thing2_robotiq_85_right_finger_tip_link" pos="0 0 0" quat="1.0 0 0 0"/>
                  </body>
                  <geom material="material_right_knuckle_0" mesh="right_knuckle" class="visual" pos="" quat=""/>
                  <geom mesh="right_knuckle" class="collision" pos="" quat=""/>
                  <geom mesh="right_finger_0" material="material_right_finger_1" class="visual" pos="-0.0315262 0 -0.00376347" quat=""/>
                  <geom mesh="right_finger_1" material="material_right_finger_0" class="visual" pos="-0.0315262 0 -0.00376347" quat=""/>
                  <geom mesh="right_finger_0" class="collision" pos="-0.0315262 0 -0.00376347" quat=""/>
                  <geom mesh="right_finger_1" class="collision" pos="-0.0315262 0 -0.00376347" quat=""/>
                  <site name="thing2_robotiq_85_right_knuckle_link" pos="0 0 0" quat="1.0 0 0 0"/>
                  <site name="thing2_robotiq_85_right_finger_link" pos="-0.03152616 0 -0.00376347" quat="1.0 0 0 0"/>
                </body>
                <body name="thing2_robotiq_85_left_inner_knuckle_link" pos="0.0127 0 0.09892" quat="-1 0 0 0">
                  <inertial pos="0.018977 0.00015001 0.022471" quat="0.939613 0 0.342237 0" mass="0.0296938" diaginertia="1.28757e-05 8.69056e-06 4.88712e-06"/>
                  <joint name="thing2_robotiq_85_left_inner_knuckle_joint" pos="0 0 0" axis="0 -1 0"/>
                  <geom mesh="left_inner_knuckle_0" material="material_left_inner_knuckle_1" class="visual" pos="" quat=""/>
                  <geom mesh="left_inner_knuckle_1" material="material_left_inner_knuckle_0" class="visual" pos="" quat=""/>
                  <geom mesh="left_inner_knuckle_0" class="collision" pos="" quat=""/>
                  <geom mesh="left_inner_knuckle_1" class="collision" pos="" quat=""/>
                  <site name="thing2_robotiq_85_left_inner_knuckle_link" pos="0 0 0" quat="1.0 0 0 0"/>
                </body>
                <body name="thing2_robotiq_85_right_inner_knuckle_link" pos="-0.0127 0 0.09892" quat="-1 0 0 0">
                  <inertial pos="-0.0192682 5.001e-05 0.0222218" quat="0.936371 0 -0.351012 0" mass="0.0296938" diaginertia="1.2882e-05 8.69056e-06 4.88076e-06"/>
                  <joint name="thing2_robotiq_85_right_inner_knuckle_joint" pos="0 0 0" axis="0 -1 0"/>
                  <geom mesh="right_inner_knuckle_0" material="material_right_inner_knuckle_1" class="visual" pos="" quat=""/>
                  <geom mesh="right_inner_knuckle_1" material="material_right_inner_knuckle_0" class="visual" pos="" quat=""/>
                  <geom mesh="right_inner_knuckle_0" class="collision" pos="" quat=""/>
                  <geom mesh="right_inner_knuckle_1" class="collision" pos="" quat=""/>
                  <site name="thing2_robotiq_85_right_inner_knuckle_link" pos="0 0 0" quat="1.0 0 0 0"/>
                </body>
                <geom mesh="wrist3_0" material="material_wrist3_1" class="visual" pos="0 0 -0.0818" quat="0.707107 0.707107 0 0"/>
                <geom mesh="wrist3_1" material="material_wrist3_0" class="visual" pos="0 0 -0.0818" quat="0.707107 0.707107 0 0"/>
                <geom mesh="wrist3_0" class="collision" pos="0 0 -0.0818" quat="0.707107 0.707107 0 0"/>
                <geom mesh="wrist3_1" class="collision" pos="0 0 -0.0818" quat="0.707107 0.707107 0 0"/>
                <geom mesh="robotiq_base_0" material="material_robotiq_base_1" class="visual" pos="0 0 0.0375" quat="-1 0 0 0"/>
                <geom mesh="robotiq_base_1" material="material_robotiq_base_0" class="visual" pos="0 0 0.0375" quat="-1 0 0 0"/>
                <geom mesh="robotiq_base_0" class="collision" pos="0 0 0.0375" quat="-1 0 0 0"/>
                <geom mesh="robotiq_base_1" class="collision" pos="0 0 0.0375" quat="-1 0 0 0"/>
                <geom pos="0 0 -0.004" quat="0.707107 0 0 -0.707107" type="mesh" mesh="robotiq_ft300-G-062-COUPLING_G-50-4M6-1D6_20181119" class="collision"/>
                <geom pos="0 0 -0.004" quat="0.707107 0 0 -0.707107" type="mesh" rgba="0.4 0.4 0.4 1" mesh="robotiq_ft300-G-062-COUPLING_G-50-4M6-1D6_20181119" class="visual"/>
                <geom pos="0 0 0.0375" quat="0 0.707107 0.707107 0" type="mesh" mesh="robotiq_ft300" class="collision"/>
                <geom pos="0 0 0.0375" quat="0 0.707107 0.707107 0" type="mesh" rgba="0.2 0.2 0.2 1" mesh="robotiq_ft300" class="visual"/>
                <site name="thing2_wrist_3_link" pos="0 0 0" quat="1.0 0 0 0"/>
                <site name="thing2_ft_frame" pos="0 0 0" quat="0 1.0 0 0"/>
                <site name="thing2_flange" pos="0 0 0" quat="-0.5000000000000001 0.5 0.5000000000000001 0.49999999999999994"/>
                <site name="thing2_tool0" pos="0 0 0" quat="1.0 0 0 0"/>
                <site name="thing2_ft300_sensor" pos="0 0 0.037500000000000006" quat="0 0.7071067811865475 0.7071067811865476 0"/>
                <site name="thing2_ft300_mounting_plate" pos="0 0 -0.004" quat="0.7071067811865476 0 0 -0.7071067811865475"/>
                <site name="thing2_robotiq_ft_frame_id" pos="0 0 0.037500000000000006" quat="1.0 0 0 0"/>
                <site name="thing2_robotiq_85_base_link" pos="0 0 0.037500000000000006" quat="1.0 0 0 0"/>
                <site name="thing2_tcp_frame" pos="0 0 0.17250000000000001" quat="1.0 0 0 0"/>
              </body>
              <geom mesh="wrist2_0" material="material_wrist2_2" class="visual" pos="0 0 -0.095" quat="1 0 0 0"/>
              <geom mesh="wrist2_1" material="material_wrist2_1" class="visual" pos="0 0 -0.095" quat="1 0 0 0"/>
              <geom mesh="wrist2_2" material="material_wrist2_0" class="visual" pos="0 0 -0.095" quat="1 0 0 0"/>
              <geom mesh="wrist2_0" class="collision" pos="0 0 -0.095" quat="1 0 0 0"/>
              <geom mesh="wrist2_1" class="collision" pos="0 0 -0.095" quat="1 0 0 0"/>
              <geom mesh="wrist2_2" class="collision" pos="0 0 -0.095" quat="1 0 0 0"/>
              <site name="thing2_wrist_2_link" pos="0 0 0" quat="1.0 0 0 0"/>
            </body>
            <geom mesh="wrist1_0" material="material_wrist1_2" class="visual" pos="0 0 -0.093" quat="0.707107 0.707107 0 0"/>
            <geom mesh="wrist1_1" material="material_wrist1_1" class="visual" pos="0 0 -0.093" quat="0.707107 0.707107 0 0"/>
            <geom mesh="wrist1_2" material="material_wrist1_0" class="visual" pos="0 0 -0.093" quat="0.707107 0.707107 0 0"/>
            <geom mesh="wrist1_0" class="collision" pos="0 0 -0.093" quat="0.707107 0.707107 0 0"/>
            <geom mesh="wrist1_1" class="collision" pos="0 0 -0.093" quat="0.707107 0.707107 0 0"/>
            <geom mesh="wrist1_2" class="collision" pos="0 0 -0.093" quat="0.707107 0.707107 0 0"/>
            <site name="thing2_wrist_1_link" pos="0 0 0" quat="1.0 0 0 0"/>
          </body>
          <geom mesh="forearm_0" material="material_forearm_2" class="visual" pos="0 0 0.0165" quat="0.5 0.5 -0.5 -0.5"/>
          <geom mesh="forearm_1" material="material_forearm_1" class="visual" pos="0 0 0.0165" quat="0.5 0.5 -0.5 -0.5"/>
          <geom mesh="forearm_2" material="material_forearm_0" class="visual" pos="0 0 0.0165" quat="0.5 0.5 -0.5 -0.5"/>
          <geom mesh="forearm_0" class="collision" pos="0 0 0.0165" quat="0.5 0.5 -0.5 -0.5"/>
          <geom mesh="forearm_1" class="collision" pos="0 0 0.0165" quat="0.5 0.5 -0.5 -0.5"/>
          <geom mesh="forearm_2" class="collision" pos="0 0 0.0165" quat="0.5 0.5 -0.5 -0.5"/>
          <site name="thing2_forearm_link" pos="0 0 0" quat="1.0 0 0 0"/>
        </body>
        <geom mesh="upperarm_0" material="material_upperarm_3" class="visual" pos="0 0 0.13585" quat="0.5 0.5 -0.5 -0.5"/>
        <geom mesh="upperarm_1" material="material_upperarm_2" class="visual" pos="0 0 0.13585" quat="0.5 0.5 -0.5 -0.5"/>
        <geom mesh="upperarm_2" material="material_upperarm_1" class="visual" pos="0 0 0.13585" quat="0.5 0.5 -0.5 -0.5"/>
        <geom mesh="upperarm_3" material="material_upperarm_0" class="visual" pos="0 0 0.13585" quat="0.5 0.5 -0.5 -0.5"/>
        <geom mesh="upperarm_0" class="collision" pos="0 0 0.13585" quat="0.5 0.5 -0.5 -0.5"/>
        <geom mesh="upperarm_1" class="collision" pos="0 0 0.13585" quat="0.5 0.5 -0.5 -0.5"/>
        <geom mesh="upperarm_2" class="collision" pos="0 0 0.13585" quat="0.5 0.5 -0.5 -0.5"/>
        <geom mesh="upperarm_3" class="collision" pos="0 0 0.13585" quat="0.5 0.5 -0.5 -0.5"/>
        <site name="thing2_upper_arm_link" pos="0 0 0" quat="1.0 0 0 0"/>
      </body>
      <geom mesh="shoulder_0" material="material_shoulder_2" class="visual" pos="" quat="0 0 0 1"/>
      <geom mesh="shoulder_1" material="material_shoulder_1" class="visual" pos="" quat="0 0 0 1"/>
      <geom mesh="shoulder_2" material="material_shoulder_0" class="visual" pos="" quat="0 0 0 1"/>
      <geom mesh="shoulder_0" class="collision" pos="" quat="0 0 0 1"/>
      <geom mesh="shoulder_1" class="collision" pos="" quat="0 0 0 1"/>
      <geom mesh="shoulder_2" class="collision" pos="" quat="0 0 0 1"/>
      <site name="thing2_shoulder_link" pos="0 0 0" quat="1.0 0 0 0"/>
    </body>
    <geom mesh="base_0" material="material_base_1" class="visual" pos="1.905 0.381 0" quat="-0.707107 0 0 -0.707107"/>
    <geom mesh="base_1" material="material_base_0" class="visual" pos="1.905 0.381 0" quat="-0.707107 0 0 -0.707107"/>
    <geom mesh="base_0" class="collision" pos="1.905 0.381 0" quat="-0.707107 0 0 -0.707107"/>
    <geom mesh="base_1" class="collision" pos="1.905 0.381 0" quat="-0.707107 0 0 -0.707107"/>
    <geom mesh="base_0" material="material_base_1" class="visual" pos="0.381 0.381 0" quat="-0.707107 0 0 -0.707107"/>
    <geom mesh="base_1" material="material_base_0" class="visual" pos="0.381 0.381 0" quat="-0.707107 0 0 -0.707107"/>
    <geom mesh="base_0" class="collision" pos="0.381 0.381 0" quat="-0.707107 0 0 -0.707107"/>
    <geom mesh="base_1" class="collision" pos="0.381 0.381 0" quat="-0.707107 0 0 -0.707107"/>
    <site name="world" pos="0 0 0" quat="1.0 0 0 0"/>
    <site name="table" pos="0 0 0" quat="1.0 0 0 0"/>
    <site name="thing1_base_link" pos="1.905 0.381 0" quat="0.7071067811865476 0 0 0.7071067811865475"/>
    <site name="thing1_base_link_inertia" pos="1.905 0.381 0" quat="0.7071067811865475 0 0 -0.7071067811865476"/>
    <site name="thing1_base" pos="1.905 0.381 0" quat="0.7071067811865475 0 0 -0.7071067811865476"/>
    <site name="thing2_base_link" pos="0.381 0.381 0" quat="0.7071067811865476 0 0 0.7071067811865475"/>
    <site name="thing2_base_link_inertia" pos="0.381 0.381 0" quat="0.7071067811865475 0 0 -0.7071067811865476"/>
    <site name="thing2_base" pos="0.381 0.381 0" quat="0.7071067811865475 0 0 -0.7071067811865476"/>
  </worldbody>
  <statistic center="0.4 0 0.4" extent="1"/>
  <visual>
    <headlight diffuse="0.6 0.6 0.6" ambient="0.1 0.1 0.1" specular="0 0 0"/>
    <rgba haze="0.15 0.25 0.35 1"/>
    <global azimuth="120" elevation="-20"/>
  </visual>
  <asset>
    <texture type="skybox" builtin="gradient" rgb1="0.3 0.5 0.7" rgb2="0 0 0" width="512" height="3072"/>
    <texture type="2d" name="groundplane" builtin="checker" mark="edge" rgb1="0.2 0.3 0.4" rgb2="0.1 0.2 0.3" markrgb="0.8 0.8 0.8" width="300" height="300"/>
    <material name="groundplane" texture="groundplane" texuniform="true" texrepeat="5 5"/>
  </asset>
  <worldbody>
    <light pos="0 0 1.5" dir="0 0 -1" directional="true"/>
    <geom name="floor" size="0 0 0.05" type="plane" material="groundplane"/>
  </worldbody>
  <option integrator="implicitfast"/>
  <default>
    <material shininess="0.25" specular="0.5"/>
    <joint armature="0.1" axis="0 1 0" range="-6.28319 6.28319"/>
    <position ctrlrange="-6.2831 6.2831"/>
    <general biastype="affine" ctrlrange="-6.2831 6.2831"/>
    <default class="size4">
      <joint damping="10"/>
      <general biasprm="0 -100000 -10000" forcerange="-330 330" gainprm="100000"/>
    </default>
    <default class="size3">
      <joint damping="5"/>
      <general biasprm="0 -40000 -4000" forcerange="-150 150" gainprm="40000"/>
      <default class="size3_limited">
        <joint range="-3.1415 3.1415"/>
        <general ctrlrange="-3.1415 3.1415"/>
      </default>
    </default>
    <default class="size2">
      <joint damping="2"/>
      <general biasprm="0 -10000 -1000" forcerange="-56 56" gainprm="10000"/>
    </default>
    <default class="visual">
      <geom conaffinity="0" contype="0" group="2" type="mesh"/>
    </default>
    <default class="collision">
      <geom group="3" type="mesh"/>
    </default>
  </default>
  <actuator>
    <position class="size4" joint="thing1_shoulder_pan_joint" name="thing1_shoulder_pan_joint"/>
    <position class="size4" joint="thing1_shoulder_lift_joint" name="thing1_shoulder_lift_joint"/>
    <position class="size3_limited" joint="thing1_elbow_joint" name="thing1_elbow_joint"/>
    <position class="size2" joint="thing1_wrist_1_joint" name="thing1_wrist_1_joint"/>
    <position class="size2" joint="thing1_wrist_2_joint" name="thing1_wrist_2_joint"/>
    <position class="size2" joint="thing1_wrist_3_joint" name="thing1_wrist_3_joint"/>
    <position ctrlrange="0.0 0.79" dampratio="1.0" forcerange="-150 150" kp="10000" name="thing1_robotiq_85_left_knuckle_joint" tendon="thing1_split"/>
    <position class="size4" joint="thing2_shoulder_pan_joint" name="thing2_shoulder_pan_joint"/>
    <position class="size4" joint="thing2_shoulder_lift_joint" name="thing2_shoulder_lift_joint"/>
    <position class="size3_limited" joint="thing2_elbow_joint" name="thing2_elbow_joint"/>
    <position class="size2" joint="thing2_wrist_1_joint" name="thing2_wrist_1_joint"/>
    <position class="size2" joint="thing2_wrist_2_joint" name="thing2_wrist_2_joint"/>
    <position class="size2" joint="thing2_wrist_3_joint" name="thing2_wrist_3_joint"/>
    <position ctrlrange="0.0 0.79" dampratio="1.0" forcerange="-150 150" kp="10000" name="thing2_robotiq_85_left_knuckle_joint" tendon="thing2_split"/>
  </actuator>
  <tendon>
    <fixed name="thing1_split">
      <joint coef="0.5" joint="thing1_robotiq_85_left_knuckle_joint"/>
      <joint coef="-0.5" joint="thing1_robotiq_85_right_knuckle_joint"/>
    </fixed>
    <fixed name="thing2_split">
      <joint coef="0.5" joint="thing2_robotiq_85_left_knuckle_joint"/>
      <joint coef="-0.5" joint="thing2_robotiq_85_right_knuckle_joint"/>
    </fixed>
  </tendon>
  <contact>
    <exclude body1="world" body2="thing1_shoulder_link"/>
    <exclude body1="thing1_wrist_3_link" body2="thing1_robotiq_85_left_knuckle_link"/>
    <exclude body1="thing1_wrist_3_link" body2="thing1_robotiq_85_left_inner_knuckle_link"/>
    <exclude body1="thing1_robotiq_85_left_inner_knuckle_link" body2="thing1_robotiq_85_left_finger_tip_link"/>
    <exclude body1="thing1_robotiq_85_left_knuckle_link" body2="thing1_robotiq_85_left_finger_tip_link"/>
    <exclude body1="thing1_wrist_3_link" body2="thing1_robotiq_85_right_knuckle_link"/>
    <exclude body1="thing1_wrist_3_link" body2="thing1_robotiq_85_right_inner_knuckle_link"/>
    <exclude body1="thing1_robotiq_85_right_inner_knuckle_link" body2="thing1_robotiq_85_right_finger_tip_link"/>
    <exclude body1="thing1_robotiq_85_right_knuckle_link" body2="thing1_robotiq_85_right_finger_tip_link"/>
    <exclude body1="thing1_robotiq_85_left_finger_tip_link" body2="thing1_robotiq_85_right_finger_tip_link"/>
    <exclude body1="world" body2="thing2_shoulder_link"/>
    <exclude body1="thing2_wrist_3_link" body2="thing2_robotiq_85_left_knuckle_link"/>
    <exclude body1="thing2_wrist_3_link" body2="thing2_robotiq_85_left_inner_knuckle_link"/>
    <exclude body1="thing2_robotiq_85_left_inner_knuckle_link" body2="thing2_robotiq_85_left_finger_tip_link"/>
    <exclude body1="thing2_robotiq_85_left_knuckle_link" body2="thing2_robotiq_85_left_finger_tip_link"/>
    <exclude body1="thing2_wrist_3_link" body2="thing2_robotiq_85_right_knuckle_link"/>
    <exclude body1="thing2_wrist_3_link" body2="thing2_robotiq_85_right_inner_knuckle_link"/>
    <exclude body1="thing2_robotiq_85_right_inner_knuckle_link" body2="thing2_robotiq_85_right_finger_tip_link"/>
    <exclude body1="thing2_robotiq_85_right_knuckle_link" body2="thing2_robotiq_85_right_finger_tip_link"/>
    <exclude body1="thing2_robotiq_85_left_finger_tip_link" body2="thing2_robotiq_85_right_finger_tip_link"/>
  </contact>
  <equality>
    <connect anchor="-0.0371575 0.0 0.043422" body1="thing1_robotiq_85_right_inner_knuckle_link" body2="thing1_robotiq_85_right_finger_tip_link" solimp="0.95 0.99 0.001" solref="0.005 1"/>
    <connect anchor="0.0371575 0.0 0.043422" body1="thing1_robotiq_85_left_inner_knuckle_link" body2="thing1_robotiq_85_left_finger_tip_link" solimp="0.95 0.99 0.001" solref="0.005 1"/>
    <joint joint1="thing1_robotiq_85_left_knuckle_joint" joint2="thing1_robotiq_85_right_knuckle_joint" polycoef="0 -1 0 0 0" solimp="0.95 0.99 0.001" solref="0.005 1"/>
    <connect anchor="-0.0371575 0.0 0.043422" body1="thing2_robotiq_85_right_inner_knuckle_link" body2="thing2_robotiq_85_right_finger_tip_link" solimp="0.95 0.99 0.001" solref="0.005 1"/>
    <connect anchor="0.0371575 0.0 0.043422" body1="thing2_robotiq_85_left_inner_knuckle_link" body2="thing2_robotiq_85_left_finger_tip_link" solimp="0.95 0.99 0.001" solref="0.005 1"/>
    <joint joint1="thing2_robotiq_85_left_knuckle_joint" joint2="thing2_robotiq_85_right_knuckle_joint" polycoef="0 -1 0 0 0" solimp="0.95 0.99 0.001" solref="0.005 1"/>
  </equality>
  <sensor>
    <force name="thing1_tcp_fts_sensor_force" site="thing1_robotiq_ft_frame_id"/>
    <torque name="thing1_tcp_fts_sensor_torque" site="thing1_robotiq_ft_frame_id"/>
  </sensor>
  <sensor>
    <force name="thing2_tcp_fts_sensor_force" site="thing2_robotiq_ft_frame_id"/>
    <torque name="thing2_tcp_fts_sensor_torque" site="thing2_robotiq_ft_frame_id"/>
  </sensor>
</mujoco>