<mujoco model="ur5_workbench">
  <compiler angle="radian" meshdir="/home/lopatoj/ur5_workbench_ws/mjcf_data/assets/" texturedir="/home/lopatoj/ur5_workbench_ws/mjcf_data/assets/"/>

  <asset>
    <mesh name="base" content_type="model/obj" file="full/base.obj"/>
    <mesh name="shoulder" content_type="model/obj" file="full/shoulder.obj"/>
    <mesh name="upperarm" content_type="model/obj" file="full/upperarm.obj"/>
    <mesh name="forearm" content_type="model/obj" file="full/forearm.obj"/>
    <mesh name="wrist1" content_type="model/obj" file="full/wrist1.obj"/>
    <mesh name="wrist2" content_type="model/obj" file="full/wrist2.obj"/>
    <mesh name="wrist3" content_type="model/obj" file="full/wrist3.obj"/>
    <mesh name="robotiq_ft300" content_type="model/stl" file="full/robotiq_ft300.stl"/>
    <mesh name="robotiq_ft300-G-062-COUPLING_G-50-4M6-1D6_20181119" content_type="model/stl" file="full/robotiq_ft300-G-062-COUPLING_G-50-4M6-1D6_20181119.stl"/>
    <mesh name="robotiq_base" content_type="model/obj" file="full/robotiq_base.obj"/>
    <mesh name="left_knuckle" content_type="model/obj" file="full/left_knuckle.obj"/>
    <mesh name="right_knuckle" content_type="model/obj" file="full/right_knuckle.obj"/>
    <mesh name="left_finger" content_type="model/obj" file="full/left_finger.obj"/>
    <mesh name="right_finger" content_type="model/obj" file="full/right_finger.obj"/>
    <mesh name="left_inner_knuckle" content_type="model/obj" file="full/left_inner_knuckle.obj"/>
    <mesh name="right_inner_knuckle" content_type="model/obj" file="full/right_inner_knuckle.obj"/>
    <mesh name="left_finger_tip" content_type="model/obj" file="full/left_finger_tip.obj"/>
    <mesh name="right_finger_tip" content_type="model/obj" file="full/right_finger_tip.obj"/>
  </asset>

  <worldbody>
    <geom pos="1.905 0.381 0" quat="-0.707107 0 0 -0.707107" type="mesh" contype="0" conaffinity="0" group="1" density="0" mesh="base"/>
    <geom pos="0.381 0.381 0" quat="-0.707107 0 0 -0.707107" type="mesh" contype="0" conaffinity="0" group="1" density="0" mesh="base"/>
    <body name="thing1_shoulder_link" pos="1.905 0.381 0.089159" quat="-0.707107 0 0 0.707107">
      <inertial pos="0 -0.00193 -0.02561" mass="3.7" diaginertia="0.0149724 0.0149724 0.0104063"/>
      <joint name="thing1_shoulder_pan_joint" pos="0 0 0" axis="0 0 1" range="-6.28319 6.28319" actuatorfrcrange="-150 150"/>
      <geom quat="0 0 0 1" type="mesh" contype="0" conaffinity="0" group="1" density="0" mesh="shoulder"/>
      <body name="thing1_upper_arm_link" quat="0.707107 0.707107 0 0">
        <inertial pos="-0.2125 0 0.11336" mass="8.393" diaginertia="0.133886 0.133886 0.0151074"/>
        <joint name="thing1_shoulder_lift_joint" pos="0 0 0" axis="0 0 1" range="-6.28319 6.28319" actuatorfrcrange="-150 150"/>
        <geom pos="0 0 0.13585" quat="0.5 0.5 -0.5 -0.5" type="mesh" contype="0" conaffinity="0" group="1" density="0" mesh="upperarm"/>
        <body name="thing1_forearm_link" pos="-0.425 0 0">
          <inertial pos="-0.24225 0 0.0265" mass="2.33" diaginertia="0.0312168 0.0312168 0.004095"/>
          <joint name="thing1_elbow_joint" pos="0 0 0" axis="0 0 1" range="-3.14159 3.14159" actuatorfrcrange="-150 150"/>
          <geom pos="0 0 0.0165" quat="0.5 0.5 -0.5 -0.5" type="mesh" contype="0" conaffinity="0" group="1" density="0" mesh="forearm"/>
          <body name="thing1_wrist_1_link" pos="-0.39225 0 0.10915">
            <inertial pos="0 -0.01634 -0.0018" quat="0.5 0.5 -0.5 0.5" mass="1.219" diaginertia="0.0021942 0.00201389 0.00201389"/>
            <joint name="thing1_wrist_1_joint" pos="0 0 0" axis="0 0 1" range="-6.28319 6.28319" actuatorfrcrange="-28 28"/>
            <geom pos="0 0 -0.093" quat="0.707107 0.707107 0 0" type="mesh" contype="0" conaffinity="0" group="1" density="0" mesh="wrist1"/>
            <body name="thing1_wrist_2_link" pos="0 -0.09465 -1.9413e-11" quat="0.707107 0.707107 0 0">
              <inertial pos="0 0.01634 -0.0018" quat="0.5 0.5 -0.5 0.5" mass="1.219" diaginertia="0.0021942 0.00183104 0.00183104"/>
              <joint name="thing1_wrist_2_joint" pos="0 0 0" axis="0 0 1" range="-6.28319 6.28319" actuatorfrcrange="-28 28"/>
              <geom pos="0 0 -0.095" quat="1 0 0 0" type="mesh" contype="0" conaffinity="0" group="1" density="0" mesh="wrist2"/>
              <body name="thing1_wrist_3_link" pos="0 0.0823 -1.688e-11" quat="0.707107 -0.707107 0 0">
                <inertial pos="-0.000226932 -0.000162966 0.0453767" quat="0.706316 -0.000320542 0.00380304 0.707886" mass="1.1511" diaginertia="0.00192005 0.00185119 0.00074602"/>
                <joint name="thing1_wrist_3_joint" pos="0 0 0" axis="0 0 1" range="-6.28319 6.28319" actuatorfrcrange="-28 28"/>
                <geom pos="0 0 -0.0818" quat="0.707107 0.707107 0 0" type="mesh" contype="0" conaffinity="0" group="1" density="0" mesh="wrist3"/>
                <geom pos="0 0 -0.004" quat="0.707107 0 0 -0.707107" type="mesh" contype="0" conaffinity="0" group="1" density="0" rgba="0.4 0.4 0.4 1" mesh="robotiq_ft300-G-062-COUPLING_G-50-4M6-1D6_20181119"/>
                <geom pos="0 0 0.0375" quat="0 0.707107 0.707107 0" type="mesh" contype="0" conaffinity="0" group="1" density="0" rgba="0.2 0.2 0.2 1" mesh="robotiq_ft300"/>
                <geom pos="0 0 0.0375" quat="-1 0 0 0" type="mesh" contype="0" conaffinity="0" group="1" density="0" mesh="robotiq_base"/>
                <body name="thing1_robotiq_85_left_knuckle_link" pos="0.0306011 0 0.0924045" quat="-1 0 0 0">
                  <inertial pos="0.0280921 -0.000550523 0.00570126" quat="0.699112 0.212074 0.213677 0.648544" mass="0.0564515" diaginertia="1.95637e-05 1.76663e-05 9.3792e-06"/>
                  <joint name="thing1_robotiq_85_left_knuckle_joint" pos="0 0 0" axis="0 -1 0" range="0 0.8" actuatorfrcrange="-50 50"/>
                  <geom type="mesh" contype="0" conaffinity="0" group="1" density="0" mesh="left_knuckle"/>
                  <geom pos="0.0315262 0 -0.00376347" type="mesh" contype="0" conaffinity="0" group="1" density="0" mesh="left_finger"/>
                  <body name="thing1_robotiq_85_left_finger_tip_link" pos="0.0371575 0 0.0434217">
                    <inertial pos="-0.0145671 -0.0008 0.016497" quat="0.977773 0 -0.209665 0" mass="0.0426859" diaginertia="1.20653e-05 1.19789e-05 2.64405e-06"/>
                    <joint name="thing1_robotiq_85_left_finger_tip_joint" pos="0 0 0" axis="0 -1 0"/>
                    <geom type="mesh" contype="0" conaffinity="0" group="1" density="0" mesh="left_finger_tip"/>
                  </body>
                </body>
                <body name="thing1_robotiq_85_right_knuckle_link" pos="-0.0306011 0 0.0924045" quat="-1 0 0 0">
                  <inertial pos="-0.0280921 4.48872e-05 0.00570126" quat="0.669099 -0.212862 -0.212522 0.679581" mass="0.0564515" diaginertia="1.95514e-05 1.7665e-05 9.37296e-06"/>
                  <joint name="thing1_robotiq_85_right_knuckle_joint" pos="0 0 0" axis="0 -1 0" range="-0.8 0" actuatorfrcrange="-50 50"/>
                  <geom type="mesh" contype="0" conaffinity="0" group="1" density="0" mesh="right_knuckle"/>
                  <geom pos="-0.0315262 0 -0.00376347" type="mesh" contype="0" conaffinity="0" group="1" density="0" mesh="right_finger"/>
                  <body name="thing1_robotiq_85_right_finger_tip_link" pos="-0.0371575 0 0.0434217">
                    <inertial pos="0.0145671 5e-05 0.016497" quat="0.977773 0 0.209665 0" mass="0.0426859" diaginertia="1.20653e-05 1.19789e-05 2.64405e-06"/>
                    <joint name="thing1_robotiq_85_right_finger_tip_joint" pos="0 0 0" axis="0 -1 0"/>
                    <geom type="mesh" contype="0" conaffinity="0" group="1" density="0" mesh="right_finger_tip"/>
                  </body>
                </body>
                <body name="thing1_robotiq_85_left_inner_knuckle_link" pos="0.0127 0 0.09892" quat="-1 0 0 0">
                  <inertial pos="0.018977 0.00015001 0.022471" quat="0.939613 0 0.342237 0" mass="0.0296938" diaginertia="1.28757e-05 8.69056e-06 4.88712e-06"/>
                  <joint name="thing1_robotiq_85_left_inner_knuckle_joint" pos="0 0 0" axis="0 -1 0"/>
                  <geom type="mesh" contype="0" conaffinity="0" group="1" density="0" mesh="left_inner_knuckle"/>
                </body>
                <body name="thing1_robotiq_85_right_inner_knuckle_link" pos="-0.0127 0 0.09892" quat="-1 0 0 0">
                  <inertial pos="-0.0192682 5.001e-05 0.0222218" quat="0.936371 0 -0.351012 0" mass="0.0296938" diaginertia="1.2882e-05 8.69056e-06 4.88076e-06"/>
                  <joint name="thing1_robotiq_85_right_inner_knuckle_joint" pos="0 0 0" axis="0 -1 0"/>
                  <geom type="mesh" contype="0" conaffinity="0" group="1" density="0" mesh="right_inner_knuckle"/>
                </body>
              </body>
            </body>
          </body>
        </body>
      </body>
    </body>
    <body name="thing2_shoulder_link" pos="0.381 0.381 0.089159" quat="-0.707107 0 0 0.707107">
      <inertial pos="0 -0.00193 -0.02561" mass="3.7" diaginertia="0.0149724 0.0149724 0.0104063"/>
      <joint name="thing2_shoulder_pan_joint" pos="0 0 0" axis="0 0 1" range="-6.28319 6.28319" actuatorfrcrange="-150 150"/>
      <geom quat="0 0 0 1" type="mesh" contype="0" conaffinity="0" group="1" density="0" mesh="shoulder"/>
      <body name="thing2_upper_arm_link" quat="0.707107 0.707107 0 0">
        <inertial pos="-0.2125 0 0.11336" mass="8.393" diaginertia="0.133886 0.133886 0.0151074"/>
        <joint name="thing2_shoulder_lift_joint" pos="0 0 0" axis="0 0 1" range="-6.28319 6.28319" actuatorfrcrange="-150 150"/>
        <geom pos="0 0 0.13585" quat="0.5 0.5 -0.5 -0.5" type="mesh" contype="0" conaffinity="0" group="1" density="0" mesh="upperarm"/>
        <body name="thing2_forearm_link" pos="-0.425 0 0">
          <inertial pos="-0.24225 0 0.0265" mass="2.33" diaginertia="0.0312168 0.0312168 0.004095"/>
          <joint name="thing2_elbow_joint" pos="0 0 0" axis="0 0 1" range="-3.14159 3.14159" actuatorfrcrange="-150 150"/>
          <geom pos="0 0 0.0165" quat="0.5 0.5 -0.5 -0.5" type="mesh" contype="0" conaffinity="0" group="1" density="0" mesh="forearm"/>
          <body name="thing2_wrist_1_link" pos="-0.39225 0 0.10915">
            <inertial pos="0 -0.01634 -0.0018" quat="0.5 0.5 -0.5 0.5" mass="1.219" diaginertia="0.0021942 0.00201389 0.00201389"/>
            <joint name="thing2_wrist_1_joint" pos="0 0 0" axis="0 0 1" range="-6.28319 6.28319" actuatorfrcrange="-28 28"/>
            <geom pos="0 0 -0.093" quat="0.707107 0.707107 0 0" type="mesh" contype="0" conaffinity="0" group="1" density="0" mesh="wrist1"/>
            <body name="thing2_wrist_2_link" pos="0 -0.09465 -1.9413e-11" quat="0.707107 0.707107 0 0">
              <inertial pos="0 0.01634 -0.0018" quat="0.5 0.5 -0.5 0.5" mass="1.219" diaginertia="0.0021942 0.00183104 0.00183104"/>
              <joint name="thing2_wrist_2_joint" pos="0 0 0" axis="0 0 1" range="-6.28319 6.28319" actuatorfrcrange="-28 28"/>
              <geom pos="0 0 -0.095" quat="1 0 0 0" type="mesh" contype="0" conaffinity="0" group="1" density="0" mesh="wrist2"/>
              <body name="thing2_wrist_3_link" pos="0 0.0823 -1.688e-11" quat="0.707107 -0.707107 0 0">
                <inertial pos="-0.000226932 -0.000162966 0.0453767" quat="0.706316 -0.000320542 0.00380304 0.707886" mass="1.1511" diaginertia="0.00192005 0.00185119 0.00074602"/>
                <joint name="thing2_wrist_3_joint" pos="0 0 0" axis="0 0 1" range="-6.28319 6.28319" actuatorfrcrange="-28 28"/>
                <geom pos="0 0 -0.0818" quat="0.707107 0.707107 0 0" type="mesh" contype="0" conaffinity="0" group="1" density="0" mesh="wrist3"/>
                <geom pos="0 0 -0.004" quat="0.707107 0 0 -0.707107" type="mesh" contype="0" conaffinity="0" group="1" density="0" rgba="0.4 0.4 0.4 1" mesh="robotiq_ft300-G-062-COUPLING_G-50-4M6-1D6_20181119"/>
                <geom pos="0 0 0.0375" quat="0 0.707107 0.707107 0" type="mesh" contype="0" conaffinity="0" group="1" density="0" rgba="0.2 0.2 0.2 1" mesh="robotiq_ft300"/>
                <geom pos="0 0 0.0375" quat="-1 0 0 0" type="mesh" contype="0" conaffinity="0" group="1" density="0" mesh="robotiq_base"/>
                <body name="thing2_robotiq_85_left_knuckle_link" pos="0.0306011 0 0.0924045" quat="-1 0 0 0">
                  <inertial pos="0.0280921 -0.000550523 0.00570126" quat="0.699112 0.212074 0.213677 0.648544" mass="0.0564515" diaginertia="1.95637e-05 1.76663e-05 9.3792e-06"/>
                  <joint name="thing2_robotiq_85_left_knuckle_joint" pos="0 0 0" axis="0 -1 0" range="0 0.8" actuatorfrcrange="-50 50"/>
                  <geom type="mesh" contype="0" conaffinity="0" group="1" density="0" mesh="left_knuckle"/>
                  <geom pos="0.0315262 0 -0.00376347" type="mesh" contype="0" conaffinity="0" group="1" density="0" mesh="left_finger"/>
                  <body name="thing2_robotiq_85_left_finger_tip_link" pos="0.0371575 0 0.0434217">
                    <inertial pos="-0.0145671 -0.0008 0.016497" quat="0.977773 0 -0.209665 0" mass="0.0426859" diaginertia="1.20653e-05 1.19789e-05 2.64405e-06"/>
                    <joint name="thing2_robotiq_85_left_finger_tip_joint" pos="0 0 0" axis="0 -1 0"/>
                    <geom type="mesh" contype="0" conaffinity="0" group="1" density="0" mesh="left_finger_tip"/>
                  </body>
                </body>
                <body name="thing2_robotiq_85_right_knuckle_link" pos="-0.0306011 0 0.0924045" quat="-1 0 0 0">
                  <inertial pos="-0.0280921 4.48872e-05 0.00570126" quat="0.669099 -0.212862 -0.212522 0.679581" mass="0.0564515" diaginertia="1.95514e-05 1.7665e-05 9.37296e-06"/>
                  <joint name="thing2_robotiq_85_right_knuckle_joint" pos="0 0 0" axis="0 -1 0" range="-0.8 0" actuatorfrcrange="-50 50"/>
                  <geom type="mesh" contype="0" conaffinity="0" group="1" density="0" mesh="right_knuckle"/>
                  <geom pos="-0.0315262 0 -0.00376347" type="mesh" contype="0" conaffinity="0" group="1" density="0" mesh="right_finger"/>
                  <body name="thing2_robotiq_85_right_finger_tip_link" pos="-0.0371575 0 0.0434217">
                    <inertial pos="0.0145671 5e-05 0.016497" quat="0.977773 0 0.209665 0" mass="0.0426859" diaginertia="1.20653e-05 1.19789e-05 2.64405e-06"/>
                    <joint name="thing2_robotiq_85_right_finger_tip_joint" pos="0 0 0" axis="0 -1 0"/>
                    <geom type="mesh" contype="0" conaffinity="0" group="1" density="0" mesh="right_finger_tip"/>
                  </body>
                </body>
                <body name="thing2_robotiq_85_left_inner_knuckle_link" pos="0.0127 0 0.09892" quat="-1 0 0 0">
                  <inertial pos="0.018977 0.00015001 0.022471" quat="0.939613 0 0.342237 0" mass="0.0296938" diaginertia="1.28757e-05 8.69056e-06 4.88712e-06"/>
                  <joint name="thing2_robotiq_85_left_inner_knuckle_joint" pos="0 0 0" axis="0 -1 0"/>
                  <geom type="mesh" contype="0" conaffinity="0" group="1" density="0" mesh="left_inner_knuckle"/>
                </body>
                <body name="thing2_robotiq_85_right_inner_knuckle_link" pos="-0.0127 0 0.09892" quat="-1 0 0 0">
                  <inertial pos="-0.0192682 5.001e-05 0.0222218" quat="0.936371 0 -0.351012 0" mass="0.0296938" diaginertia="1.2882e-05 8.69056e-06 4.88076e-06"/>
                  <joint name="thing2_robotiq_85_right_inner_knuckle_joint" pos="0 0 0" axis="0 -1 0"/>
                  <geom type="mesh" contype="0" conaffinity="0" group="1" density="0" mesh="right_inner_knuckle"/>
                </body>
              </body>
            </body>
          </body>
        </body>
      </body>
    </body>
    <body name="falling_box">
      <inertial pos="0 0 0" mass="0.01" diaginertia="1 1 1"/>
      <joint name="falling_box_joint" type="free"/>
      <geom size="0.025 0.025 0.025" type="box" contype="0" conaffinity="0" group="1" density="0"/>
    </body>
  </worldbody>
</mujoco>
