<?xml version="1.0" ?>
<!-- =================================================================================== -->
<!-- |    This document was autogenerated by xacro from /home/lopatoj/ur5_workbench_ws/install/ur5_workbench_mujoco_config/share/ur5_workbench_mujoco_config/urdf/ur5_workbench.mujoco_ros2_control.xacro | -->
<!-- |    EDITING THIS FILE BY HAND IS NOT RECOMMENDED                                 | -->
<!-- =================================================================================== -->
<robot name="ur5_workbench">
	<!--
    Base UR robot series xacro macro.
    NOTE this is NOT a URDF. It cannot directly be loaded by consumers
    expecting a flattened '.urdf' file. See the top-level '.xacro' for that
    (but note that .xacro must still be processed by the xacro command).
    This file models the base kinematic chain of a UR robot, which then gets
    parameterised by various configuration files to convert it into a UR3(e),
    UR5(e), UR10(e) or UR16e, etc.
    NOTE the default kinematic parameters (i.e., link lengths, frame locations,
    offsets, etc) do not correspond to any particular robot. They are defaults
    only. There WILL be non-zero offsets between the Forward Kinematics results
    in TF (i.e., robot_state_publisher) and the values reported by the Teach
    Pendant.
    For accurate (and robot-specific) transforms, the 'kinematics_parameters_file'
    parameter MUST point to a .yaml file containing the appropriate values for
    the targeted robot.
    If using the UniversalRobots/Universal_Robots_ROS_Driver, follow the steps
    described in the readme of that repository to extract the kinematic
    calibration from the controller and generate the required .yaml file.
    Main author of the migration to yaml configs Ludovic Delval.
    Contributors to previous versions (in no particular order)
     - Denis Stogl
     - Lovro Ivanov
     - Felix Messmer
     - Kelsey Hawkins
     - Wim Meeussen
     - Shaun Edwards
     - Nadia Hammoudeh Garcia
     - Dave Hershberger
     - G. vd. Hoorn
     - Philip Long
     - Dave Coleman
     - Miguel Prada
     - Mathias Luedtke
     - Marcel Schnirring
     - Felix von Drigalski
     - Felix Exner
     - Jimmy Da Silva
     - Ajit Krisshna N L
     - Muhammad Asif Rana
  -->
	<link name="world"/>
	<joint name="table_joint" type="fixed">
		<origin rpy="0 0 0" xyz="0 0 0"/>
		<parent link="world"/>
		<child link="table"/>
	</joint>
	<link name="table"/>
	<!-- links -  main serial chain -->
	<!-- base_link serves as the root of the robot's kinematic tree. It follows REP-103
        conventions (i.e., X+ forward, Y+ left, Z+ up).
        Since some kinematic solvers forbid having inertia values attached to a root link, we've
        added the base_link_inertia link that carries the visual, collision and inertia
        information.
    -->
	<link name="thing1_base_link"/>
	<link name="thing1_base_link_inertia">
		<visual>
			<origin rpy="0 0 3.141592653589793" xyz="0 0 0"/>
			<geometry>
				<mesh filename="full/base.obj"/>
			</geometry>
		</visual>
		<inertial>
			<mass value="4.0"/>
			<origin rpy="0 0 0" xyz="0 0 0"/>
			<inertia ixx="0.00443333156" ixy="0.0" ixz="0.0" iyy="0.00443333156" iyz="0.0" izz="0.0072"/>
		</inertial>
	</link>
	<link name="thing1_shoulder_link">
		<visual>
			<origin rpy="0 0 3.141592653589793" xyz="0 0 0"/>
			<geometry>
				<mesh filename="full/shoulder.obj"/>
			</geometry>
		</visual>
		<inertial>
			<mass value="3.7"/>
			<origin rpy="0 0 0" xyz="0.0 -0.00193 -0.02561"/>
			<inertia ixx="0.014972358333333331" ixy="0" ixz="0" iyy="0.014972358333333331" iyz="0" izz="0.01040625"/>
		</inertial>
	</link>
	<link name="thing1_upper_arm_link">
		<visual>
			<origin rpy="1.5707963267948966 0 -1.5707963267948966" xyz="0 0 0.13585"/>
			<geometry>
				<mesh filename="full/upperarm.obj"/>
			</geometry>
		</visual>
		<inertial>
			<mass value="8.393"/>
			<origin rpy="0 1.570796326794897 0" xyz="-0.2125 0.0 0.11336"/>
			<inertia ixx="0.13388583541666665" ixy="0" ixz="0" iyy="0.13388583541666665" iyz="0" izz="0.0151074"/>
		</inertial>
	</link>
	<link name="thing1_forearm_link">
		<visual>
			<origin rpy="1.5707963267948966 0 -1.5707963267948966" xyz="0 0 0.0165"/>
			<geometry>
				<mesh filename="full/forearm.obj"/>
			</geometry>
		</visual>
		<inertial>
			<mass value="2.33"/>
			<origin rpy="0 1.570796326794897 0" xyz="-0.24225 0.0 0.0265"/>
			<inertia ixx="0.031216803515624995" ixy="0" ixz="0" iyy="0.031216803515624995" iyz="0" izz="0.004095"/>
		</inertial>
	</link>
	<link name="thing1_wrist_1_link">
		<visual>
			<origin rpy="1.5707963267948966 0 0" xyz="0 0 -0.093"/>
			<geometry>
				<mesh filename="full/wrist1.obj"/>
			</geometry>
		</visual>
		<inertial>
			<mass value="1.219"/>
			<origin rpy="0 0 0" xyz="0.0 -0.01634 -0.0018"/>
			<inertia ixx="0.002013889583333333" ixy="0" ixz="0" iyy="0.002013889583333333" iyz="0" izz="0.0021942"/>
		</inertial>
	</link>
	<link name="thing1_wrist_2_link">
		<visual>
			<origin rpy="0 0 0" xyz="0 0 -0.095"/>
			<geometry>
				<mesh filename="full/wrist2.obj"/>
			</geometry>
		</visual>
		<inertial>
			<mass value="1.219"/>
			<origin rpy="0 0 0" xyz="0.0 0.01634 -0.0018"/>
			<inertia ixx="0.0018310395833333333" ixy="0" ixz="0" iyy="0.0018310395833333333" iyz="0" izz="0.0021942"/>
		</inertial>
	</link>
	<link name="thing1_wrist_3_link">
		<visual>
			<origin rpy="1.5707963267948966 0 0" xyz="0 0 -0.0818"/>
			<geometry>
				<mesh filename="full/wrist3.obj"/>
			</geometry>
		</visual>
		<inertial>
			<mass value="0.1879"/>
			<origin rpy="0 0 0" xyz="0.0 0.0 -0.001159"/>
			<inertia ixx="8.062475833333332e-05" ixy="0" ixz="0" iyy="8.062475833333332e-05" iyz="0" izz="0.0001321171875"/>
		</inertial>
	</link>
	<!-- base_joint fixes base_link to the environment -->
	<joint name="thing1_base_joint" type="fixed">
		<origin rpy="0 0 1.5707963267948966" xyz="1.905 0.381 0"/>
		<parent link="table"/>
		<child link="thing1_base_link"/>
	</joint>
	<!-- joints - main serial chain -->
	<joint name="thing1_base_link-base_link_inertia" type="fixed">
		<parent link="thing1_base_link"/>
		<child link="thing1_base_link_inertia"/>
		<!-- 'base_link' is REP-103 aligned (so X+ forward), while the internal
           frames of the robot/controller have X+ pointing backwards.
           Use the joint between 'base_link' and 'base_link_inertia' (a dummy
           link/frame) to introduce the necessary rotation over Z (of pi rad).
      -->
		<origin rpy="0 0 3.141592653589793" xyz="0 0 0"/>
	</joint>
	<joint name="thing1_shoulder_pan_joint" type="revolute">
		<parent link="thing1_base_link_inertia"/>
		<child link="thing1_shoulder_link"/>
		<origin rpy="0 0 0" xyz="0 0 0.089159"/>
		<axis xyz="0 0 1"/>
		<limit effort="150.0" lower="-6.283185307179586" upper="6.283185307179586" velocity="3.141592653589793"/>
		<dynamics damping="0" friction="0"/>
	</joint>
	<joint name="thing1_shoulder_lift_joint" type="revolute">
		<parent link="thing1_shoulder_link"/>
		<child link="thing1_upper_arm_link"/>
		<origin rpy="1.570796327 0 0" xyz="0 0 0"/>
		<axis xyz="0 0 1"/>
		<limit effort="150.0" lower="-6.283185307179586" upper="6.283185307179586" velocity="3.141592653589793"/>
		<dynamics damping="0" friction="0"/>
	</joint>
	<joint name="thing1_elbow_joint" type="revolute">
		<parent link="thing1_upper_arm_link"/>
		<child link="thing1_forearm_link"/>
		<origin rpy="0 0 0" xyz="-0.425 0 0"/>
		<axis xyz="0 0 1"/>
		<limit effort="150.0" lower="-3.141592653589793" upper="3.141592653589793" velocity="3.141592653589793"/>
		<dynamics damping="0" friction="0"/>
	</joint>
	<joint name="thing1_wrist_1_joint" type="revolute">
		<parent link="thing1_forearm_link"/>
		<child link="thing1_wrist_1_link"/>
		<origin rpy="0 0 0" xyz="-0.39225 0 0.10915"/>
		<axis xyz="0 0 1"/>
		<limit effort="28.0" lower="-6.283185307179586" upper="6.283185307179586" velocity="3.141592653589793"/>
		<dynamics damping="0" friction="0"/>
	</joint>
	<joint name="thing1_wrist_2_joint" type="revolute">
		<parent link="thing1_wrist_1_link"/>
		<child link="thing1_wrist_2_link"/>
		<origin rpy="1.570796327 0 0" xyz="0 -0.09465 -1.941303950897609e-11"/>
		<axis xyz="0 0 1"/>
		<limit effort="28.0" lower="-6.283185307179586" upper="6.283185307179586" velocity="3.141592653589793"/>
		<dynamics damping="0" friction="0"/>
	</joint>
	<joint name="thing1_wrist_3_joint" type="revolute">
		<parent link="thing1_wrist_2_link"/>
		<child link="thing1_wrist_3_link"/>
		<origin rpy="1.570796326589793 3.141592653589793 3.141592653589793" xyz="0 0.0823 -1.688001216681175e-11"/>
		<axis xyz="0 0 1"/>
		<limit effort="28.0" lower="-6.283185307179586" upper="6.283185307179586" velocity="3.141592653589793"/>
		<dynamics damping="0" friction="0"/>
	</joint>
	<link name="thing1_ft_frame"/>
	<joint name="thing1_wrist_3_link-ft_frame" type="fixed">
		<parent link="thing1_wrist_3_link"/>
		<child link="thing1_ft_frame"/>
		<origin rpy="3.141592653589793 0 0" xyz="0 0 0"/>
	</joint>
	<!-- ROS-Industrial 'base' frame - base_link to UR 'Base' Coordinates transform -->
	<link name="thing1_base"/>
	<joint name="thing1_base_link-base_fixed_joint" type="fixed">
		<!-- Note the rotation over Z of pi radians - as base_link is REP-103
           aligned (i.e., has X+ forward, Y+ left and Z+ up), this is needed
           to correctly align 'base' with the 'Base' coordinate system of
           the UR controller.
      -->
		<origin rpy="0 0 3.141592653589793" xyz="0 0 0"/>
		<parent link="thing1_base_link"/>
		<child link="thing1_base"/>
	</joint>
	<!-- ROS-Industrial 'flange' frame - attachment point for EEF models -->
	<link name="thing1_flange"/>
	<joint name="thing1_wrist_3-flange" type="fixed">
		<parent link="thing1_wrist_3_link"/>
		<child link="thing1_flange"/>
		<origin rpy="0 -1.5707963267948966 -1.5707963267948966" xyz="0 0 0"/>
	</joint>
	<!-- ROS-Industrial 'tool0' frame - all-zeros tool frame -->
	<link name="thing1_tool0"/>
	<joint name="thing1_flange-tool0" type="fixed">
		<!-- default toolframe - X+ left, Y+ up, Z+ front -->
		<origin rpy="1.5707963267948966 0 1.5707963267948966" xyz="0 0 0"/>
		<parent link="thing1_flange"/>
		<child link="thing1_tool0"/>
	</joint>
	<!-- mount the fts to the robot -->
	<joint name="thing1_ft300_fix" type="fixed">
		<origin rpy="0 0 -1.5707963267948966" xyz="0 0 -0.004"/>
		<parent link="thing1_tool0"/>
		<child link="thing1_ft300_mounting_plate"/>
	</joint>
	<!-- Link representing the FT300 force-torque sensor -->
	<link name="thing1_ft300_sensor">
		<inertial>
			<origin rpy="0 0 0" xyz="0 0 -0.017"/>
			<mass value="0.300"/>
			<inertia ixx="0.000262" ixy="0" ixz="1e-06" iyx="0" iyy="0.000265" iyz="1e-06" izx="-1e-06" izy="1e-06" izz="0.000219"/>
		</inertial>
		<visual>
			<origin rpy="0 0 0" xyz="0 0 0"/>
			<geometry>
				<mesh filename="full/robotiq_ft300.stl"/>
			</geometry>
			<material name="Robotiq-Black">
				<color rgba="0.2 0.2 0.2 1.0"/>
			</material>
		</visual>
	</link>
	<!-- Link representing the FT300 mounting plate -->
	<link name="thing1_ft300_mounting_plate">
		<visual>
			<origin rpy="0 0 0" xyz="0 0 0"/>
			<geometry>
				<mesh filename="full/robotiq_ft300-G-062-COUPLING_G-50-4M6-1D6_20181119.stl"/>
			</geometry>
			<material name="Robotiq-Grey">
				<color rgba="0.4 0.4 0.4 1.0"/>
			</material>
		</visual>
	</link>
	<!-- Connect force sensor with mounting/coupling plate -->
	<joint name="thing1_ft300_mounting_plate" type="fixed">
		<origin rpy="0 3.141592653589793 0" xyz="0 0 0.0415"/>
		<parent link="thing1_ft300_mounting_plate"/>
		<child link="thing1_ft300_sensor"/>
	</joint>
	<joint name="thing1_measurment_joint" type="fixed">
		<origin rpy="0 3.141592653589793 -1.5707963267948966" xyz="0 0 0"/>
		<parent link="thing1_ft300_sensor"/>
		<child link="thing1_robotiq_ft_frame_id"/>
	</joint>
	<link name="thing1_robotiq_ft_frame_id"/>
	<link name="thing1_robotiq_85_base_link">
		<visual>
			<geometry>
				<mesh filename="full/robotiq_base.obj"/>
			</geometry>
		</visual>
		<inertial>
			<origin rpy="0 0 0" xyz="0.0 2.274e-05 0.03232288"/>
			<mass value="6.6320197e-01"/>
			<inertia ixx="5.1617816e-04" ixy="2.936e-8" ixz="0.0" iyy="5.8802208e-04" iyz="-3.2296e-7" izz="3.9462776e-04"/>
		</inertial>
	</link>
	<link name="thing1_robotiq_85_left_knuckle_link">
		<visual>
			<geometry>
				<mesh filename="full/left_knuckle.obj"/>
			</geometry>
		</visual>
		<inertial>
			<origin rpy="0 0 0" xyz="0.01213197 0.0002 -0.00058647"/>
			<mass value="1.384773208e-02"/>
			<inertia ixx="3.5232e-7" ixy="0.0" ixz="1.1744e-7" iyy="2.31944e-6" iyz="0" izz="2.23136e-6"/>
		</inertial>
	</link>
	<link name="thing1_robotiq_85_right_knuckle_link">
		<visual>
			<geometry>
				<mesh filename="full/right_knuckle.obj"/>
			</geometry>
		</visual>
		<inertial>
			<origin rpy="0 0 0" xyz="-0.01213197 0.0002 -0.00058647"/>
			<mass value="1.384773208e-02"/>
			<inertia ixx="3.5232e-7" ixy="0.0" ixz="-1.1744e-7" iyy="2.31944e-6" iyz="0.0" izz="2.23136e-6"/>
		</inertial>
	</link>
	<link name="thing1_robotiq_85_left_finger_link">
		<visual>
			<geometry>
				<mesh filename="full/left_finger.obj"/>
			</geometry>
		</visual>
		<inertial>
			<origin rpy="0 0 0" xyz="0.00346899 -0.00079447 0.01867121"/>
			<mass value="4.260376752e-02"/>
			<inertia ixx="1.385792000000000e-05" ixy="0.0" ixz="-2.17264e-06" iyy="1.183208e-05" iyz="0.0" izz="5.19672e-06"/>
		</inertial>
	</link>
	<link name="thing1_robotiq_85_right_finger_link">
		<visual>
			<geometry>
				<mesh filename="full/right_finger.obj"/>
			</geometry>
		</visual>
		<inertial>
			<origin rpy="0 0 0" xyz="-0.00346899 -5.53e-06 0.01867121"/>
			<mass value="4.260376752000000e-02"/>
			<inertia ixx="1.385792e-05" ixy="0.0" ixz="2.17264e-06" iyy="1.183208e-05" iyz="0.0" izz="5.19672e-06"/>
		</inertial>
	</link>
	<link name="thing1_robotiq_85_left_inner_knuckle_link">
		<visual>
			<geometry>
				<mesh filename="full/left_inner_knuckle.obj"/>
			</geometry>
		</visual>
		<inertial>
			<origin rpy="0 0 0" xyz="0.01897699 0.00015001 0.02247101"/>
			<mass value="2.969376448e-02"/>
			<inertia ixx="9.57136e-06" ixy="0.0" ixz="-3.93424e-06" iyy="8.69056e-06" iyz="0.0" izz="8.19144e-06"/>
		</inertial>
	</link>
	<link name="thing1_robotiq_85_right_inner_knuckle_link">
		<visual>
			<geometry>
				<mesh filename="full/right_inner_knuckle.obj"/>
			</geometry>
		</visual>
		<inertial>
			<origin rpy="0 0 0" xyz="-0.01926824 5.001e-05 0.02222178"/>
			<mass value="2.969376448e-02"/>
			<inertia ixx="9.42456e-06" ixy="0.0" ixz="3.9636e-06" iyy="8.69056e-06" iyz="0.0" izz="8.33824e-06"/>
		</inertial>
	</link>
	<link name="thing1_robotiq_85_left_finger_tip_link">
		<visual>
			<geometry>
				<mesh filename="full/left_finger_tip.obj"/>
			</geometry>
		</visual>
		<inertial>
			<origin rpy="0 0 0" xyz="-0.01456706 -0.0008 0.01649701"/>
			<mass value="4.268588744e-02"/>
			<inertia ixx="1.048152e-05" ixy="0.0" ixz="3.5232e-6" iyy="1.197888e-05" iyz="0.0" izz="4.22784e-06"/>
		</inertial>
	</link>
	<link name="thing1_robotiq_85_right_finger_tip_link">
		<visual>
			<geometry>
				<mesh filename="full/right_finger_tip.obj"/>
			</geometry>
		</visual>
		<inertial>
			<origin rpy="0 0 0" xyz="0.01456706 5e-05 0.01649701"/>
			<mass value="4.268588744e-02"/>
			<inertia ixx="1.048152e-05" ixy="0.0" ixz="-3.5232e-06" iyy="1.197888e-05" iyz="0.0" izz="4.22784e-06"/>
		</inertial>
	</link>
	<joint name="thing1_robotiq_85_base_joint" type="fixed">
		<parent link="thing1_robotiq_ft_frame_id"/>
		<child link="thing1_robotiq_85_base_link"/>
		<origin rpy="0 0 0" xyz="0 0 0"/>
	</joint>
	<joint name="thing1_robotiq_85_left_knuckle_joint" type="revolute">
		<parent link="thing1_robotiq_85_base_link"/>
		<child link="thing1_robotiq_85_left_knuckle_link"/>
		<axis xyz="0 -1 0"/>
		<origin rpy="0 0 0" xyz="0.03060114 0.0 0.05490452"/>
		<limit effort="50" lower="0.0" upper="0.8" velocity="0.5"/>
	</joint>
	<joint name="thing1_robotiq_85_right_knuckle_joint" type="revolute">
		<parent link="thing1_robotiq_85_base_link"/>
		<child link="thing1_robotiq_85_right_knuckle_link"/>
		<axis xyz="0 -1 0"/>
		<origin rpy="0 0 0" xyz="-0.03060114 0.0 0.05490452"/>
		<limit effort="50" lower="-0.8" upper="0.0" velocity="0.5"/>
		<mimic joint="thing1_robotiq_85_left_knuckle_joint" multiplier="-1"/>
	</joint>
	<joint name="thing1_robotiq_85_left_finger_joint" type="fixed">
		<parent link="thing1_robotiq_85_left_knuckle_link"/>
		<child link="thing1_robotiq_85_left_finger_link"/>
		<origin rpy="0 0 0" xyz="0.03152616 0.0 -0.00376347"/>
	</joint>
	<joint name="thing1_robotiq_85_right_finger_joint" type="fixed">
		<parent link="thing1_robotiq_85_right_knuckle_link"/>
		<child link="thing1_robotiq_85_right_finger_link"/>
		<origin rpy="0 0 0" xyz="-0.03152616 0.0 -0.00376347"/>
	</joint>
	<joint name="thing1_robotiq_85_left_inner_knuckle_joint" type="continuous">
		<parent link="thing1_robotiq_85_base_link"/>
		<child link="thing1_robotiq_85_left_inner_knuckle_link"/>
		<axis xyz="0 -1 0"/>
		<origin rpy="0 0 0" xyz="0.0127 0.0 0.06142"/>
		<mimic joint="thing1_robotiq_85_left_knuckle_joint"/>
	</joint>
	<joint name="thing1_robotiq_85_right_inner_knuckle_joint" type="continuous">
		<parent link="thing1_robotiq_85_base_link"/>
		<child link="thing1_robotiq_85_right_inner_knuckle_link"/>
		<axis xyz="0 -1 0"/>
		<origin rpy="0 0 0" xyz="-0.0127 0.0 0.06142"/>
		<mimic joint="thing1_robotiq_85_left_knuckle_joint" multiplier="-1"/>
	</joint>
	<joint name="thing1_robotiq_85_left_finger_tip_joint" type="continuous">
		<parent link="thing1_robotiq_85_left_finger_link"/>
		<child link="thing1_robotiq_85_left_finger_tip_link"/>
		<axis xyz="0 -1 0"/>
		<origin rpy="0 0 0" xyz="0.00563134 0.0 0.04718515"/>
		<mimic joint="thing1_robotiq_85_left_knuckle_joint" multiplier="-1"/>
	</joint>
	<joint name="thing1_robotiq_85_right_finger_tip_joint" type="continuous">
		<parent link="thing1_robotiq_85_right_finger_link"/>
		<child link="thing1_robotiq_85_right_finger_tip_link"/>
		<axis xyz="0 -1 0"/>
		<origin rpy="0 0 0" xyz="-0.00563134 0.0 0.04718515"/>
		<mimic joint="thing1_robotiq_85_left_knuckle_joint"/>
	</joint>
	<!-- links -  main serial chain -->
	<!-- base_link serves as the root of the robot's kinematic tree. It follows REP-103
        conventions (i.e., X+ forward, Y+ left, Z+ up).
        Since some kinematic solvers forbid having inertia values attached to a root link, we've
        added the base_link_inertia link that carries the visual, collision and inertia
        information.
    -->
	<link name="thing2_base_link"/>
	<link name="thing2_base_link_inertia">
		<visual>
			<origin rpy="0 0 3.141592653589793" xyz="0 0 0"/>
			<geometry>
				<mesh filename="full/base.obj"/>
			</geometry>
		</visual>
		<inertial>
			<mass value="4.0"/>
			<origin rpy="0 0 0" xyz="0 0 0"/>
			<inertia ixx="0.00443333156" ixy="0.0" ixz="0.0" iyy="0.00443333156" iyz="0.0" izz="0.0072"/>
		</inertial>
	</link>
	<link name="thing2_shoulder_link">
		<visual>
			<origin rpy="0 0 3.141592653589793" xyz="0 0 0"/>
			<geometry>
				<mesh filename="full/shoulder.obj"/>
			</geometry>
		</visual>
		<inertial>
			<mass value="3.7"/>
			<origin rpy="0 0 0" xyz="0.0 -0.00193 -0.02561"/>
			<inertia ixx="0.014972358333333331" ixy="0" ixz="0" iyy="0.014972358333333331" iyz="0" izz="0.01040625"/>
		</inertial>
	</link>
	<link name="thing2_upper_arm_link">
		<visual>
			<origin rpy="1.5707963267948966 0 -1.5707963267948966" xyz="0 0 0.13585"/>
			<geometry>
				<mesh filename="full/upperarm.obj"/>
			</geometry>
		</visual>
		<inertial>
			<mass value="8.393"/>
			<origin rpy="0 1.570796326794897 0" xyz="-0.2125 0.0 0.11336"/>
			<inertia ixx="0.13388583541666665" ixy="0" ixz="0" iyy="0.13388583541666665" iyz="0" izz="0.0151074"/>
		</inertial>
	</link>
	<link name="thing2_forearm_link">
		<visual>
			<origin rpy="1.5707963267948966 0 -1.5707963267948966" xyz="0 0 0.0165"/>
			<geometry>
				<mesh filename="full/forearm.obj"/>
			</geometry>
		</visual>
		<inertial>
			<mass value="2.33"/>
			<origin rpy="0 1.570796326794897 0" xyz="-0.24225 0.0 0.0265"/>
			<inertia ixx="0.031216803515624995" ixy="0" ixz="0" iyy="0.031216803515624995" iyz="0" izz="0.004095"/>
		</inertial>
	</link>
	<link name="thing2_wrist_1_link">
		<visual>
			<origin rpy="1.5707963267948966 0 0" xyz="0 0 -0.093"/>
			<geometry>
				<mesh filename="full/wrist1.obj"/>
			</geometry>
		</visual>
		<inertial>
			<mass value="1.219"/>
			<origin rpy="0 0 0" xyz="0.0 -0.01634 -0.0018"/>
			<inertia ixx="0.002013889583333333" ixy="0" ixz="0" iyy="0.002013889583333333" iyz="0" izz="0.0021942"/>
		</inertial>
	</link>
	<link name="thing2_wrist_2_link">
		<visual>
			<origin rpy="0 0 0" xyz="0 0 -0.095"/>
			<geometry>
				<mesh filename="full/wrist2.obj"/>
			</geometry>
		</visual>
		<inertial>
			<mass value="1.219"/>
			<origin rpy="0 0 0" xyz="0.0 0.01634 -0.0018"/>
			<inertia ixx="0.0018310395833333333" ixy="0" ixz="0" iyy="0.0018310395833333333" iyz="0" izz="0.0021942"/>
		</inertial>
	</link>
	<link name="thing2_wrist_3_link">
		<visual>
			<origin rpy="1.5707963267948966 0 0" xyz="0 0 -0.0818"/>
			<geometry>
				<mesh filename="full/wrist3.obj"/>
			</geometry>
		</visual>
		<inertial>
			<mass value="0.1879"/>
			<origin rpy="0 0 0" xyz="0.0 0.0 -0.001159"/>
			<inertia ixx="8.062475833333332e-05" ixy="0" ixz="0" iyy="8.062475833333332e-05" iyz="0" izz="0.0001321171875"/>
		</inertial>
	</link>
	<!-- base_joint fixes base_link to the environment -->
	<joint name="thing2_base_joint" type="fixed">
		<origin rpy="0 0 1.5707963267948966" xyz="0.381 0.381 0"/>
		<parent link="table"/>
		<child link="thing2_base_link"/>
	</joint>
	<!-- joints - main serial chain -->
	<joint name="thing2_base_link-base_link_inertia" type="fixed">
		<parent link="thing2_base_link"/>
		<child link="thing2_base_link_inertia"/>
		<!-- 'base_link' is REP-103 aligned (so X+ forward), while the internal
           frames of the robot/controller have X+ pointing backwards.
           Use the joint between 'base_link' and 'base_link_inertia' (a dummy
           link/frame) to introduce the necessary rotation over Z (of pi rad).
      -->
		<origin rpy="0 0 3.141592653589793" xyz="0 0 0"/>
	</joint>
	<joint name="thing2_shoulder_pan_joint" type="revolute">
		<parent link="thing2_base_link_inertia"/>
		<child link="thing2_shoulder_link"/>
		<origin rpy="0 0 0" xyz="0 0 0.089159"/>
		<axis xyz="0 0 1"/>
		<limit effort="150.0" lower="-6.283185307179586" upper="6.283185307179586" velocity="3.141592653589793"/>
		<dynamics damping="0" friction="0"/>
	</joint>
	<joint name="thing2_shoulder_lift_joint" type="revolute">
		<parent link="thing2_shoulder_link"/>
		<child link="thing2_upper_arm_link"/>
		<origin rpy="1.570796327 0 0" xyz="0 0 0"/>
		<axis xyz="0 0 1"/>
		<limit effort="150.0" lower="-6.283185307179586" upper="6.283185307179586" velocity="3.141592653589793"/>
		<dynamics damping="0" friction="0"/>
	</joint>
	<joint name="thing2_elbow_joint" type="revolute">
		<parent link="thing2_upper_arm_link"/>
		<child link="thing2_forearm_link"/>
		<origin rpy="0 0 0" xyz="-0.425 0 0"/>
		<axis xyz="0 0 1"/>
		<limit effort="150.0" lower="-3.141592653589793" upper="3.141592653589793" velocity="3.141592653589793"/>
		<dynamics damping="0" friction="0"/>
	</joint>
	<joint name="thing2_wrist_1_joint" type="revolute">
		<parent link="thing2_forearm_link"/>
		<child link="thing2_wrist_1_link"/>
		<origin rpy="0 0 0" xyz="-0.39225 0 0.10915"/>
		<axis xyz="0 0 1"/>
		<limit effort="28.0" lower="-6.283185307179586" upper="6.283185307179586" velocity="3.141592653589793"/>
		<dynamics damping="0" friction="0"/>
	</joint>
	<joint name="thing2_wrist_2_joint" type="revolute">
		<parent link="thing2_wrist_1_link"/>
		<child link="thing2_wrist_2_link"/>
		<origin rpy="1.570796327 0 0" xyz="0 -0.09465 -1.941303950897609e-11"/>
		<axis xyz="0 0 1"/>
		<limit effort="28.0" lower="-6.283185307179586" upper="6.283185307179586" velocity="3.141592653589793"/>
		<dynamics damping="0" friction="0"/>
	</joint>
	<joint name="thing2_wrist_3_joint" type="revolute">
		<parent link="thing2_wrist_2_link"/>
		<child link="thing2_wrist_3_link"/>
		<origin rpy="1.570796326589793 3.141592653589793 3.141592653589793" xyz="0 0.0823 -1.688001216681175e-11"/>
		<axis xyz="0 0 1"/>
		<limit effort="28.0" lower="-6.283185307179586" upper="6.283185307179586" velocity="3.141592653589793"/>
		<dynamics damping="0" friction="0"/>
	</joint>
	<link name="thing2_ft_frame"/>
	<joint name="thing2_wrist_3_link-ft_frame" type="fixed">
		<parent link="thing2_wrist_3_link"/>
		<child link="thing2_ft_frame"/>
		<origin rpy="3.141592653589793 0 0" xyz="0 0 0"/>
	</joint>
	<!-- ROS-Industrial 'base' frame - base_link to UR 'Base' Coordinates transform -->
	<link name="thing2_base"/>
	<joint name="thing2_base_link-base_fixed_joint" type="fixed">
		<!-- Note the rotation over Z of pi radians - as base_link is REP-103
           aligned (i.e., has X+ forward, Y+ left and Z+ up), this is needed
           to correctly align 'base' with the 'Base' coordinate system of
           the UR controller.
      -->
		<origin rpy="0 0 3.141592653589793" xyz="0 0 0"/>
		<parent link="thing2_base_link"/>
		<child link="thing2_base"/>
	</joint>
	<!-- ROS-Industrial 'flange' frame - attachment point for EEF models -->
	<link name="thing2_flange"/>
	<joint name="thing2_wrist_3-flange" type="fixed">
		<parent link="thing2_wrist_3_link"/>
		<child link="thing2_flange"/>
		<origin rpy="0 -1.5707963267948966 -1.5707963267948966" xyz="0 0 0"/>
	</joint>
	<!-- ROS-Industrial 'tool0' frame - all-zeros tool frame -->
	<link name="thing2_tool0"/>
	<joint name="thing2_flange-tool0" type="fixed">
		<!-- default toolframe - X+ left, Y+ up, Z+ front -->
		<origin rpy="1.5707963267948966 0 1.5707963267948966" xyz="0 0 0"/>
		<parent link="thing2_flange"/>
		<child link="thing2_tool0"/>
	</joint>
	<!-- mount the fts to the robot -->
	<joint name="thing2_ft300_fix" type="fixed">
		<origin rpy="0 0 -1.5707963267948966" xyz="0 0 -0.004"/>
		<parent link="thing2_tool0"/>
		<child link="thing2_ft300_mounting_plate"/>
	</joint>
	<!-- Link representing the FT300 force-torque sensor -->
	<link name="thing2_ft300_sensor">
		<inertial>
			<origin rpy="0 0 0" xyz="0 0 -0.017"/>
			<mass value="0.300"/>
			<inertia ixx="0.000262" ixy="0" ixz="1e-06" iyx="0" iyy="0.000265" iyz="1e-06" izx="-1e-06" izy="1e-06" izz="0.000219"/>
		</inertial>
		<visual>
			<origin rpy="0 0 0" xyz="0 0 0"/>
			<geometry>
				<mesh filename="full/robotiq_ft300.stl"/>
			</geometry>
			<material name="Robotiq-Black">
				<color rgba="0.2 0.2 0.2 1.0"/>
			</material>
		</visual>
	</link>
	<!-- Link representing the FT300 mounting plate -->
	<link name="thing2_ft300_mounting_plate">
		<visual>
			<origin rpy="0 0 0" xyz="0 0 0"/>
			<geometry>
				<mesh filename="full/robotiq_ft300-G-062-COUPLING_G-50-4M6-1D6_20181119.stl"/>
			</geometry>
			<material name="Robotiq-Grey">
				<color rgba="0.4 0.4 0.4 1.0"/>
			</material>
		</visual>
	</link>
	<!-- Connect force sensor with mounting/coupling plate -->
	<joint name="thing2_ft300_mounting_plate" type="fixed">
		<origin rpy="0 3.141592653589793 0" xyz="0 0 0.0415"/>
		<parent link="thing2_ft300_mounting_plate"/>
		<child link="thing2_ft300_sensor"/>
	</joint>
	<joint name="thing2_measurment_joint" type="fixed">
		<origin rpy="0 3.141592653589793 -1.5707963267948966" xyz="0 0 0"/>
		<parent link="thing2_ft300_sensor"/>
		<child link="thing2_robotiq_ft_frame_id"/>
	</joint>
	<link name="thing2_robotiq_ft_frame_id"/>
	<link name="thing2_robotiq_85_base_link">
		<visual>
			<geometry>
				<mesh filename="full/robotiq_base.obj"/>
			</geometry>
		</visual>
		<inertial>
			<origin rpy="0 0 0" xyz="0.0 2.274e-05 0.03232288"/>
			<mass value="6.6320197e-01"/>
			<inertia ixx="5.1617816e-04" ixy="2.936e-8" ixz="0.0" iyy="5.8802208e-04" iyz="-3.2296e-7" izz="3.9462776e-04"/>
		</inertial>
	</link>
	<link name="thing2_robotiq_85_left_knuckle_link">
		<visual>
			<geometry>
				<mesh filename="full/left_knuckle.obj"/>
			</geometry>
		</visual>
		<inertial>
			<origin rpy="0 0 0" xyz="0.01213197 0.0002 -0.00058647"/>
			<mass value="1.384773208e-02"/>
			<inertia ixx="3.5232e-7" ixy="0.0" ixz="1.1744e-7" iyy="2.31944e-6" iyz="0" izz="2.23136e-6"/>
		</inertial>
	</link>
	<link name="thing2_robotiq_85_right_knuckle_link">
		<visual>
			<geometry>
				<mesh filename="full/right_knuckle.obj"/>
			</geometry>
		</visual>
		<inertial>
			<origin rpy="0 0 0" xyz="-0.01213197 0.0002 -0.00058647"/>
			<mass value="1.384773208e-02"/>
			<inertia ixx="3.5232e-7" ixy="0.0" ixz="-1.1744e-7" iyy="2.31944e-6" iyz="0.0" izz="2.23136e-6"/>
		</inertial>
	</link>
	<link name="thing2_robotiq_85_left_finger_link">
		<visual>
			<geometry>
				<mesh filename="full/left_finger.obj"/>
			</geometry>
		</visual>
		<inertial>
			<origin rpy="0 0 0" xyz="0.00346899 -0.00079447 0.01867121"/>
			<mass value="4.260376752e-02"/>
			<inertia ixx="1.385792000000000e-05" ixy="0.0" ixz="-2.17264e-06" iyy="1.183208e-05" iyz="0.0" izz="5.19672e-06"/>
		</inertial>
	</link>
	<link name="thing2_robotiq_85_right_finger_link">
		<visual>
			<geometry>
				<mesh filename="full/right_finger.obj"/>
			</geometry>
		</visual>
		<inertial>
			<origin rpy="0 0 0" xyz="-0.00346899 -5.53e-06 0.01867121"/>
			<mass value="4.260376752000000e-02"/>
			<inertia ixx="1.385792e-05" ixy="0.0" ixz="2.17264e-06" iyy="1.183208e-05" iyz="0.0" izz="5.19672e-06"/>
		</inertial>
	</link>
	<link name="thing2_robotiq_85_left_inner_knuckle_link">
		<visual>
			<geometry>
				<mesh filename="full/left_inner_knuckle.obj"/>
			</geometry>
		</visual>
		<inertial>
			<origin rpy="0 0 0" xyz="0.01897699 0.00015001 0.02247101"/>
			<mass value="2.969376448e-02"/>
			<inertia ixx="9.57136e-06" ixy="0.0" ixz="-3.93424e-06" iyy="8.69056e-06" iyz="0.0" izz="8.19144e-06"/>
		</inertial>
	</link>
	<link name="thing2_robotiq_85_right_inner_knuckle_link">
		<visual>
			<geometry>
				<mesh filename="full/right_inner_knuckle.obj"/>
			</geometry>
		</visual>
		<inertial>
			<origin rpy="0 0 0" xyz="-0.01926824 5.001e-05 0.02222178"/>
			<mass value="2.969376448e-02"/>
			<inertia ixx="9.42456e-06" ixy="0.0" ixz="3.9636e-06" iyy="8.69056e-06" iyz="0.0" izz="8.33824e-06"/>
		</inertial>
	</link>
	<link name="thing2_robotiq_85_left_finger_tip_link">
		<visual>
			<geometry>
				<mesh filename="full/left_finger_tip.obj"/>
			</geometry>
		</visual>
		<inertial>
			<origin rpy="0 0 0" xyz="-0.01456706 -0.0008 0.01649701"/>
			<mass value="4.268588744e-02"/>
			<inertia ixx="1.048152e-05" ixy="0.0" ixz="3.5232e-6" iyy="1.197888e-05" iyz="0.0" izz="4.22784e-06"/>
		</inertial>
	</link>
	<link name="thing2_robotiq_85_right_finger_tip_link">
		<visual>
			<geometry>
				<mesh filename="full/right_finger_tip.obj"/>
			</geometry>
		</visual>
		<inertial>
			<origin rpy="0 0 0" xyz="0.01456706 5e-05 0.01649701"/>
			<mass value="4.268588744e-02"/>
			<inertia ixx="1.048152e-05" ixy="0.0" ixz="-3.5232e-06" iyy="1.197888e-05" iyz="0.0" izz="4.22784e-06"/>
		</inertial>
	</link>
	<joint name="thing2_robotiq_85_base_joint" type="fixed">
		<parent link="thing2_robotiq_ft_frame_id"/>
		<child link="thing2_robotiq_85_base_link"/>
		<origin rpy="0 0 0" xyz="0 0 0"/>
	</joint>
	<joint name="thing2_robotiq_85_left_knuckle_joint" type="revolute">
		<parent link="thing2_robotiq_85_base_link"/>
		<child link="thing2_robotiq_85_left_knuckle_link"/>
		<axis xyz="0 -1 0"/>
		<origin rpy="0 0 0" xyz="0.03060114 0.0 0.05490452"/>
		<limit effort="50" lower="0.0" upper="0.8" velocity="0.5"/>
	</joint>
	<joint name="thing2_robotiq_85_right_knuckle_joint" type="revolute">
		<parent link="thing2_robotiq_85_base_link"/>
		<child link="thing2_robotiq_85_right_knuckle_link"/>
		<axis xyz="0 -1 0"/>
		<origin rpy="0 0 0" xyz="-0.03060114 0.0 0.05490452"/>
		<limit effort="50" lower="-0.8" upper="0.0" velocity="0.5"/>
		<mimic joint="thing2_robotiq_85_left_knuckle_joint" multiplier="-1"/>
	</joint>
	<joint name="thing2_robotiq_85_left_finger_joint" type="fixed">
		<parent link="thing2_robotiq_85_left_knuckle_link"/>
		<child link="thing2_robotiq_85_left_finger_link"/>
		<origin rpy="0 0 0" xyz="0.03152616 0.0 -0.00376347"/>
	</joint>
	<joint name="thing2_robotiq_85_right_finger_joint" type="fixed">
		<parent link="thing2_robotiq_85_right_knuckle_link"/>
		<child link="thing2_robotiq_85_right_finger_link"/>
		<origin rpy="0 0 0" xyz="-0.03152616 0.0 -0.00376347"/>
	</joint>
	<joint name="thing2_robotiq_85_left_inner_knuckle_joint" type="continuous">
		<parent link="thing2_robotiq_85_base_link"/>
		<child link="thing2_robotiq_85_left_inner_knuckle_link"/>
		<axis xyz="0 -1 0"/>
		<origin rpy="0 0 0" xyz="0.0127 0.0 0.06142"/>
		<mimic joint="thing2_robotiq_85_left_knuckle_joint"/>
	</joint>
	<joint name="thing2_robotiq_85_right_inner_knuckle_joint" type="continuous">
		<parent link="thing2_robotiq_85_base_link"/>
		<child link="thing2_robotiq_85_right_inner_knuckle_link"/>
		<axis xyz="0 -1 0"/>
		<origin rpy="0 0 0" xyz="-0.0127 0.0 0.06142"/>
		<mimic joint="thing2_robotiq_85_left_knuckle_joint" multiplier="-1"/>
	</joint>
	<joint name="thing2_robotiq_85_left_finger_tip_joint" type="continuous">
		<parent link="thing2_robotiq_85_left_finger_link"/>
		<child link="thing2_robotiq_85_left_finger_tip_link"/>
		<axis xyz="0 -1 0"/>
		<origin rpy="0 0 0" xyz="0.00563134 0.0 0.04718515"/>
		<mimic joint="thing2_robotiq_85_left_knuckle_joint" multiplier="-1"/>
	</joint>
	<joint name="thing2_robotiq_85_right_finger_tip_joint" type="continuous">
		<parent link="thing2_robotiq_85_right_finger_link"/>
		<child link="thing2_robotiq_85_right_finger_tip_link"/>
		<axis xyz="0 -1 0"/>
		<origin rpy="0 0 0" xyz="-0.00563134 0.0 0.04718515"/>
		<mimic joint="thing2_robotiq_85_left_knuckle_joint"/>
	</joint>
	<mujoco_inputs>
		<raw_inputs>
			<option integrator="implicitfast"/>
			<default>
				<geom condim="4" friction="2.0 0.5 0.0001" solimp="0.95 0.99 0.001" solref="0.004 1"/>
				<material shininess="0.25" specular="0.5"/>
				<joint armature="0.1" axis="0 1 0" range="-6.28319 6.28319"/>
				<position ctrlrange="-6.2831 6.2831"/>
				<general biastype="affine" ctrlrange="-6.2831 6.2831"/>
				<default class="size4">
					<joint damping="10"/>
					<general biasprm="0 -100000 -10000" forcerange="-330 330" gainprm="100000"/>
				</default>
				<default class="size3">
					<joint damping="5"/>
					<general biasprm="0 -40000 -4000" forcerange="-150 150" gainprm="40000"/>
					<default class="size3_limited">
						<joint range="-3.1415 3.1415"/>
						<general ctrlrange="-3.1415 3.1415"/>
					</default>
				</default>
				<default class="size2">
					<joint damping="2"/>
					<general biasprm="0 -10000 -1000" forcerange="-56 56" gainprm="10000"/>
				</default>
				<default class="visual">
					<geom conaffinity="0" contype="0" group="2" type="mesh"/>
				</default>
				<default class="collision">
					<geom group="3" type="mesh"/>
				</default>
			</default>
			<actuator>
				<position class="size4" joint="thing1_shoulder_pan_joint" name="thing1_shoulder_pan_joint"/>
				<position class="size4" joint="thing1_shoulder_lift_joint" name="thing1_shoulder_lift_joint"/>
				<position class="size3_limited" joint="thing1_elbow_joint" name="thing1_elbow_joint"/>
				<position class="size2" joint="thing1_wrist_1_joint" name="thing1_wrist_1_joint"/>
				<position class="size2" joint="thing1_wrist_2_joint" name="thing1_wrist_2_joint"/>
				<position class="size2" joint="thing1_wrist_3_joint" name="thing1_wrist_3_joint"/>
				<position ctrlrange="0.0 0.79" dampratio="1.0" forcerange="-150 150" kp="10000" name="thing1_robotiq_85_left_knuckle_joint" tendon="thing1_split"/>
				<position class="size4" joint="thing2_shoulder_pan_joint" name="thing2_shoulder_pan_joint"/>
				<position class="size4" joint="thing2_shoulder_lift_joint" name="thing2_shoulder_lift_joint"/>
				<position class="size3_limited" joint="thing2_elbow_joint" name="thing2_elbow_joint"/>
				<position class="size2" joint="thing2_wrist_1_joint" name="thing2_wrist_1_joint"/>
				<position class="size2" joint="thing2_wrist_2_joint" name="thing2_wrist_2_joint"/>
				<position class="size2" joint="thing2_wrist_3_joint" name="thing2_wrist_3_joint"/>
				<position ctrlrange="0.0 0.79" dampratio="1.0" forcerange="-150 150" kp="10000" name="thing2_robotiq_85_left_knuckle_joint" tendon="thing2_split"/>
			</actuator>
			<tendon>
				<fixed name="thing1_split">
					<joint coef="0.5" joint="thing1_robotiq_85_left_knuckle_joint"/>
					<joint coef="-0.5" joint="thing1_robotiq_85_right_knuckle_joint"/>
				</fixed>
				<fixed name="thing2_split">
					<joint coef="0.5" joint="thing2_robotiq_85_left_knuckle_joint"/>
					<joint coef="-0.5" joint="thing2_robotiq_85_right_knuckle_joint"/>
				</fixed>
			</tendon>
			<contact>
				<exclude body1="world" body2="thing1_shoulder_link"/>
				<exclude body1="thing1_wrist_3_link" body2="thing1_robotiq_85_left_knuckle_link"/>
				<exclude body1="thing1_wrist_3_link" body2="thing1_robotiq_85_left_inner_knuckle_link"/>
				<exclude body1="thing1_robotiq_85_left_inner_knuckle_link" body2="thing1_robotiq_85_left_finger_tip_link"/>
				<exclude body1="thing1_robotiq_85_left_knuckle_link" body2="thing1_robotiq_85_left_finger_tip_link"/>
				<exclude body1="thing1_wrist_3_link" body2="thing1_robotiq_85_right_knuckle_link"/>
				<exclude body1="thing1_wrist_3_link" body2="thing1_robotiq_85_right_inner_knuckle_link"/>
				<exclude body1="thing1_robotiq_85_right_inner_knuckle_link" body2="thing1_robotiq_85_right_finger_tip_link"/>
				<exclude body1="thing1_robotiq_85_right_knuckle_link" body2="thing1_robotiq_85_right_finger_tip_link"/>
				<exclude body1="thing1_robotiq_85_left_finger_tip_link" body2="thing1_robotiq_85_right_finger_tip_link"/>
				<exclude body1="world" body2="thing2_shoulder_link"/>
				<exclude body1="thing2_wrist_3_link" body2="thing2_robotiq_85_left_knuckle_link"/>
				<exclude body1="thing2_wrist_3_link" body2="thing2_robotiq_85_left_inner_knuckle_link"/>
				<exclude body1="thing2_robotiq_85_left_inner_knuckle_link" body2="thing2_robotiq_85_left_finger_tip_link"/>
				<exclude body1="thing2_robotiq_85_left_knuckle_link" body2="thing2_robotiq_85_left_finger_tip_link"/>
				<exclude body1="thing2_wrist_3_link" body2="thing2_robotiq_85_right_knuckle_link"/>
				<exclude body1="thing2_wrist_3_link" body2="thing2_robotiq_85_right_inner_knuckle_link"/>
				<exclude body1="thing2_robotiq_85_right_inner_knuckle_link" body2="thing2_robotiq_85_right_finger_tip_link"/>
				<exclude body1="thing2_robotiq_85_right_knuckle_link" body2="thing2_robotiq_85_right_finger_tip_link"/>
				<exclude body1="thing2_robotiq_85_left_finger_tip_link" body2="thing2_robotiq_85_right_finger_tip_link"/>
			</contact>
			<equality>
				<connect anchor="-0.0371575 0.0 0.043422" body1="thing1_robotiq_85_right_inner_knuckle_link" body2="thing1_robotiq_85_right_finger_tip_link" solimp="0.95 0.99 0.001" solref="0.005 1"/>
				<connect anchor="0.0371575 0.0 0.043422" body1="thing1_robotiq_85_left_inner_knuckle_link" body2="thing1_robotiq_85_left_finger_tip_link" solimp="0.95 0.99 0.001" solref="0.005 1"/>
				<joint joint1="thing1_robotiq_85_left_knuckle_joint" joint2="thing1_robotiq_85_right_knuckle_joint" polycoef="0 -1 0 0 0" solimp="0.95 0.99 0.001" solref="0.005 1"/>
				<connect anchor="-0.0371575 0.0 0.043422" body1="thing2_robotiq_85_right_inner_knuckle_link" body2="thing2_robotiq_85_right_finger_tip_link" solimp="0.95 0.99 0.001" solref="0.005 1"/>
				<connect anchor="0.0371575 0.0 0.043422" body1="thing2_robotiq_85_left_inner_knuckle_link" body2="thing2_robotiq_85_left_finger_tip_link" solimp="0.95 0.99 0.001" solref="0.005 1"/>
				<joint joint1="thing2_robotiq_85_left_knuckle_joint" joint2="thing2_robotiq_85_right_knuckle_joint" polycoef="0 -1 0 0 0" solimp="0.95 0.99 0.001" solref="0.005 1"/>
			</equality>
			<sensor>
				<force name="thing1_tcp_fts_sensor_force" site="thing1_robotiq_ft_frame_id"/>
				<torque name="thing1_tcp_fts_sensor_torque" site="thing1_robotiq_ft_frame_id"/>
			</sensor>
			<sensor>
				<force name="thing2_tcp_fts_sensor_force" site="thing2_robotiq_ft_frame_id"/>
				<torque name="thing2_tcp_fts_sensor_torque" site="thing2_robotiq_ft_frame_id"/>
			</sensor>
		</raw_inputs>
		<processed_inputs>
			<modify_element armature="0.5" frictionloss="5.0" name="thing1_robotiq_85_left_knuckle_joint" type="joint"/>
			<modify_element armature="0.5" frictionloss="5.0" name="thing1_robotiq_85_right_knuckle_joint" type="joint"/>
			<modify_element armature="0.5" frictionloss="5.0" name="thing2_robotiq_85_left_knuckle_joint" type="joint"/>
			<modify_element armature="0.5" frictionloss="5.0" name="thing2_robotiq_85_right_knuckle_joint" type="joint"/>
		</processed_inputs>
	</mujoco_inputs>
	<joint name="falling_box_joint" type="floating">
		<origin rpy="0 0 0" xyz="0 0 0"/>
		<parent link="world"/>
		<child link="falling_box"/>
	</joint>
	<link name="falling_box">
		<inertial>
			<mass value="0.01"/>
			<inertia ixx="1.0" ixy="0.0" ixz="0.0" iyy="1.0" iyz="0.0" izz="1.0"/>
		</inertial>
		<visual>
			<geometry>
				<box size="0.05 0.05 0.05"/>
			</geometry>
		</visual>
	</link>
	<ros2_control name="MujocoSystem" type="system">
		<hardware>
			<plugin>mujoco_ros2_control/MujocoSystemInterface</plugin>
			<param name="sim_speed_factor">1.0</param>
		</hardware>
		<joint name="thing1_shoulder_pan_joint">
			<state_interface name="position">
				<param name="initial_value">0.0</param>
			</state_interface>
			<state_interface name="velocity"/>
			<state_interface name="effort"/>
			<command_interface name="position"/>
		</joint>
		<joint name="thing1_shoulder_lift_joint">
			<state_interface name="position">
				<param name="initial_value">-1.5707963267948966</param>
			</state_interface>
			<state_interface name="velocity"/>
			<state_interface name="effort"/>
			<command_interface name="position"/>
		</joint>
		<joint name="thing1_elbow_joint">
			<state_interface name="position">
				<param name="initial_value">0.0</param>
			</state_interface>
			<state_interface name="velocity"/>
			<state_interface name="effort"/>
			<command_interface name="position"/>
		</joint>
		<joint name="thing1_wrist_1_joint">
			<state_interface name="position">
				<param name="initial_value">-1.5707963267948966</param>
			</state_interface>
			<state_interface name="velocity"/>
			<state_interface name="effort"/>
			<command_interface name="position"/>
		</joint>
		<joint name="thing1_wrist_2_joint">
			<state_interface name="position">
				<param name="initial_value">0.0</param>
			</state_interface>
			<state_interface name="velocity"/>
			<state_interface name="effort"/>
			<command_interface name="position"/>
		</joint>
		<joint name="thing1_wrist_3_joint">
			<state_interface name="position">
				<param name="initial_value">0.0</param>
			</state_interface>
			<state_interface name="velocity"/>
			<state_interface name="effort"/>
			<command_interface name="position"/>
		</joint>
		<joint name="thing1_robotiq_85_left_knuckle_joint">
			<state_interface name="position">
				<param name="initial_value">0.0</param>
			</state_interface>
			<state_interface name="velocity"/>
			<state_interface name="effort"/>
			<command_interface name="position"/>
		</joint>
		<sensor name="thing1_tcp_fts_sensor">
			<param name="mujoco_type">fts</param>
			<param name="mujoco_sensor_name">thing1_tcp_fts_sensor</param>
			<state_interface name="force.x"/>
			<state_interface name="force.y"/>
			<state_interface name="force.z"/>
			<state_interface name="torque.x"/>
			<state_interface name="torque.y"/>
			<state_interface name="torque.z"/>
		</sensor>
		<joint name="thing2_shoulder_pan_joint">
			<state_interface name="position">
				<param name="initial_value">0.0</param>
			</state_interface>
			<state_interface name="velocity"/>
			<state_interface name="effort"/>
			<command_interface name="position"/>
		</joint>
		<joint name="thing2_shoulder_lift_joint">
			<state_interface name="position">
				<param name="initial_value">-1.5707963267948966</param>
			</state_interface>
			<state_interface name="velocity"/>
			<state_interface name="effort"/>
			<command_interface name="position"/>
		</joint>
		<joint name="thing2_elbow_joint">
			<state_interface name="position">
				<param name="initial_value">0.0</param>
			</state_interface>
			<state_interface name="velocity"/>
			<state_interface name="effort"/>
			<command_interface name="position"/>
		</joint>
		<joint name="thing2_wrist_1_joint">
			<state_interface name="position">
				<param name="initial_value">-1.5707963267948966</param>
			</state_interface>
			<state_interface name="velocity"/>
			<state_interface name="effort"/>
			<command_interface name="position"/>
		</joint>
		<joint name="thing2_wrist_2_joint">
			<state_interface name="position">
				<param name="initial_value">0.0</param>
			</state_interface>
			<state_interface name="velocity"/>
			<state_interface name="effort"/>
			<command_interface name="position"/>
		</joint>
		<joint name="thing2_wrist_3_joint">
			<state_interface name="position">
				<param name="initial_value">0.0</param>
			</state_interface>
			<state_interface name="velocity"/>
			<state_interface name="effort"/>
			<command_interface name="position"/>
		</joint>
		<joint name="thing2_robotiq_85_left_knuckle_joint">
			<state_interface name="position">
				<param name="initial_value">0.0</param>
			</state_interface>
			<state_interface name="velocity"/>
			<state_interface name="effort"/>
			<command_interface name="position"/>
		</joint>
		<sensor name="thing2_tcp_fts_sensor">
			<param name="mujoco_type">fts</param>
			<param name="mujoco_sensor_name">thing2_tcp_fts_sensor</param>
			<state_interface name="force.x"/>
			<state_interface name="force.y"/>
			<state_interface name="force.z"/>
			<state_interface name="torque.x"/>
			<state_interface name="torque.y"/>
			<state_interface name="torque.z"/>
		</sensor>
		<joint name="falling_box_joint"/>
	</ros2_control>
	<mujoco>
		<compiler assetdir="/home/lopatoj/ur5_workbench_ws/mjcf_data/assets" balanceinertia="true" discardvisual="false" strippath="false"/>
	</mujoco>
</robot>